Workbook

Sheet Ringkasan Mingguan 2026
A1: RINGKASAN GROWTH IPH MINGGUAN JANUARI - AGUSTUS 2026 (Pasar Pon Jombang)
A3: No | B3: Bulan - Minggu | C3: Rentang Tanggal | D3: Growth IPH (%) | E3: Arah | F3: Growth IPH (%) [utk grafik]
A4: 1 | B4: Jan 2026 - M1 | C4: 2026-01-01 s/d 2026-01-02 | D4: ='Perhitungan IPH Mingguan 2026'!F26 -> 0.0074147116 | E4: =IF(ISNUMBER(D4),IF(D4>0,"Naik",IF(D4<0,"Turun","Tetap")),"-") -> Naik | F4: =IFERROR(IF(ISNUMBER(D4),D4,NA()),NA()) -> 0.0074147116
A5: 2 | B5: Jan 2026 - M2 | C5: 2026-01-05 s/d 2026-01-09 | D5: ='Perhitungan IPH Mingguan 2026'!I26 -> 0.0074147116 | E5: =IF(ISNUMBER(D5),IF(D5>0,"Naik",IF(D5<0,"Turun","Tetap")),"-") -> Naik | F5: =IFERROR(IF(ISNUMBER(D5),D5,NA()),NA()) -> 0.0074147116
A6: 3 | B6: Jan 2026 - M3 | C6: 2026-01-12 s/d 2026-01-16 | D6: ='Perhitungan IPH Mingguan 2026'!L26 -> -0.025212905 | E6: =IF(ISNUMBER(D6),IF(D6>0,"Naik",IF(D6<0,"Turun","Tetap")),"-") -> Turun | F6: =IFERROR(IF(ISNUMBER(D6),D6,NA()),NA()) -> -0.025212905
A7: 4 | B7: Jan 2026 - M4 | C7: 2026-01-19 s/d 2026-01-23 | D7: ='Perhitungan IPH Mingguan 2026'!O26 -> 0.24701179 | E7: =IF(ISNUMBER(D7),IF(D7>0,"Naik",IF(D7<0,"Turun","Tetap")),"-") -> Naik | F7: =IFERROR(IF(ISNUMBER(D7),D7,NA()),NA()) -> 0.24701179
A8: 5 | B8: Jan 2026 - M5 | C8: 2026-01-26 s/d 2026-01-30 | D8: ='Perhitungan IPH Mingguan 2026'!R26 -> 0.49375015 | E8: =IF(ISNUMBER(D8),IF(D8>0,"Naik",IF(D8<0,"Turun","Tetap")),"-") -> Naik | F8: =IFERROR(IF(ISNUMBER(D8),D8,NA()),NA()) -> 0.49375015
A9: 6 | B9: Feb 2026 - M1 | C9: 2026-02-02 s/d 2026-02-06 | D9: ='Perhitungan IPH Mingguan 2026'!U26 -> 2.1969477 | E9: =IF(ISNUMBER(D9),IF(D9>0,"Naik",IF(D9<0,"Turun","Tetap")),"-") -> Naik | F9: =IFERROR(IF(ISNUMBER(D9),D9,NA()),NA()) -> 2.1969477
A10: 7 | B10: Feb 2026 - M2 | C10: 2026-02-09 s/d 2026-02-13 | D10: ='Perhitungan IPH Mingguan 2026'!X26 -> 0.68139888 | E10: =IF(ISNUMBER(D10),IF(D10>0,"Naik",IF(D10<0,"Turun","Tetap")),"-") -> Naik | F10: =IFERROR(IF(ISNUMBER(D10),D10,NA()),NA()) -> 0.68139888
A11: 8 | B11: Feb 2026 - M3 | C11: 2026-02-16 s/d 2026-02-20 | D11: ='Perhitungan IPH Mingguan 2026'!AA26 -> 7.1853199 | E11: =IF(ISNUMBER(D11),IF(D11>0,"Naik",IF(D11<0,"Turun","Tetap")),"-") -> Naik | F11: =IFERROR(IF(ISNUMBER(D11),D11,NA()),NA()) -> 7.1853199
A12: 9 | B12: Feb 2026 - M4 | C12: 2026-02-23 s/d 2026-02-27 | D12: ='Perhitungan IPH Mingguan 2026'!AD26 -> 6.7936501 | E12: =IF(ISNUMBER(D12),IF(D12>0,"Naik",IF(D12<0,"Turun","Tetap")),"-") -> Naik | F12: =IFERROR(IF(ISNUMBER(D12),D12,NA()),NA()) -> 6.7936501
A13: 10 | B13: Mar 2026 - M1 | C13: 2026-03-02 s/d 2026-03-06 | D13: ='Perhitungan IPH Mingguan 2026'!AG26 -> 4.688364 | E13: =IF(ISNUMBER(D13),IF(D13>0,"Naik",IF(D13<0,"Turun","Tetap")),"-") -> Naik | F13: =IFERROR(IF(ISNUMBER(D13),D13,NA()),NA()) -> 4.688364
A14: 11 | B14: Mar 2026 - M2 | C14: 2026-03-09 s/d 2026-03-13 | D14: ='Perhitungan IPH Mingguan 2026'!AJ26 -> 5.326732 | E14: =IF(ISNUMBER(D14),IF(D14>0,"Naik",IF(D14<0,"Turun","Tetap")),"-") -> Naik | F14: =IFERROR(IF(ISNUMBER(D14),D14,NA()),NA()) -> 5.326732
A15: 12 | B15: Mar 2026 - M3 | C15: 2026-03-16 s/d 2026-03-20 | D15: ='Perhitungan IPH Mingguan 2026'!AM26 -> 7.4413094 | E15: =IF(ISNUMBER(D15),IF(D15>0,"Naik",IF(D15<0,"Turun","Tetap")),"-") -> Naik | F15: =IFERROR(IF(ISNUMBER(D15),D15,NA()),NA()) -> 7.4413094
A16: 13 | B16: Mar 2026 - M4 | C16: 2026-03-23 s/d 2026-03-27 | D16: ='Perhitungan IPH Mingguan 2026'!AP26 -> 6.3668818 | E16: =IF(ISNUMBER(D16),IF(D16>0,"Naik",IF(D16<0,"Turun","Tetap")),"-") -> Naik | F16: =IFERROR(IF(ISNUMBER(D16),D16,NA()),NA()) -> 6.3668818
A17: 14 | B17: Mar 2026 - M5 | C17: 2026-03-30 s/d 2026-03-31 | D17: ='Perhitungan IPH Mingguan 2026'!AS26 -> 5.9991495 | E17: =IF(ISNUMBER(D17),IF(D17>0,"Naik",IF(D17<0,"Turun","Tetap")),"-") -> Naik | F17: =IFERROR(IF(ISNUMBER(D17),D17,NA()),NA()) -> 5.9991495
A18: 15 | B18: Apr 2026 - M1 | C18: 2026-04-01 s/d 2026-04-03 | D18: ='Perhitungan IPH Mingguan 2026'!AV26 -> -0.38464926 | E18: =IF(ISNUMBER(D18),IF(D18>0,"Naik",IF(D18<0,"Turun","Tetap")),"-") -> Turun | F18: =IFERROR(IF(ISNUMBER(D18),D18,NA()),NA()) -> -0.38464926
A19: 16 | B19: Apr 2026 - M2 | C19: 2026-04-06 s/d 2026-04-10 | D19: ='Perhitungan IPH Mingguan 2026'!AY26 -> -0.75503837 | E19: =IF(ISNUMBER(D19),IF(D19>0,"Naik",IF(D19<0,"Turun","Tetap")),"-") -> Turun | F19: =IFERROR(IF(ISNUMBER(D19),D19,NA()),NA()) -> -0.75503837
A20: 17 | B20: Apr 2026 - M3 | C20: 2026-04-13 s/d 2026-04-17 | D20: ='Perhitungan IPH Mingguan 2026'!BB26 -> -0.92014615 | E20: =IF(ISNUMBER(D20),IF(D20>0,"Naik",IF(D20<0,"Turun","Tetap")),"-") -> Turun | F20: =IFERROR(IF(ISNUMBER(D20),D20,NA()),NA()) -> -0.92014615
A21: 18 | B21: Apr 2026 - M4 | C21: 2026-04-20 s/d 2026-04-24 | D21: ='Perhitungan IPH Mingguan 2026'!BE26 -> -0.32346223 | E21: =IF(ISNUMBER(D21),IF(D21>0,"Naik",IF(D21<0,"Turun","Tetap")),"-") -> Turun | F21: =IFERROR(IF(ISNUMBER(D21),D21,NA()),NA()) -> -0.32346223
A22: 19 | B22: Apr 2026 - M5 | C22: 2026-04-27 s/d 2026-04-30 | D22: ='Perhitungan IPH Mingguan 2026'!BH26 -> -0.26717913 | E22: =IF(ISNUMBER(D22),IF(D22>0,"Naik",IF(D22<0,"Turun","Tetap")),"-") -> Turun | F22: =IFERROR(IF(ISNUMBER(D22),D22,NA()),NA()) -> -0.26717913
A23: 20 | B23: Mei 2026 - M1 | C23: 2026-05-01 s/d 2026-05-01 | D23: ='Perhitungan IPH Mingguan 2026'!BK26 -> Data tidak tersedia | E23: =IF(ISNUMBER(D23),IF(D23>0,"Naik",IF(D23<0,"Turun","Tetap")),"-") -> - | F23: =IFERROR(IF(ISNUMBER(D23),D23,NA()),NA()) -> #N/A
A24: 21 | B24: Mei 2026 - M2 | C24: 2026-05-04 s/d 2026-05-08 | D24: ='Perhitungan IPH Mingguan 2026'!BN26 -> 1.4009085 | E24: =IF(ISNUMBER(D24),IF(D24>0,"Naik",IF(D24<0,"Turun","Tetap")),"-") -> Naik | F24: =IFERROR(IF(ISNUMBER(D24),D24,NA()),NA()) -> 1.4009085
A25: 22 | B25: Mei 2026 - M3 | C25: 2026-05-11 s/d 2026-05-15 | D25: ='Perhitungan IPH Mingguan 2026'!BQ26 -> 1.7151216 | E25: =IF(ISNUMBER(D25),IF(D25>0,"Naik",IF(D25<0,"Turun","Tetap")),"-") -> Naik | F25: =IFERROR(IF(ISNUMBER(D25),D25,NA()),NA()) -> 1.7151216
A26: 23 | B26: Mei 2026 - M4 | C26: 2026-05-18 s/d 2026-05-22 | D26: ='Perhitungan IPH Mingguan 2026'!BT26 -> 1.5616209 | E26: =IF(ISNUMBER(D26),IF(D26>0,"Naik",IF(D26<0,"Turun","Tetap")),"-") -> Naik | F26: =IFERROR(IF(ISNUMBER(D26),D26,NA()),NA()) -> 1.5616209
A27: 24 | B27: Mei 2026 - M5 | C27: 2026-05-25 s/d 2026-05-29 | D27: ='Perhitungan IPH Mingguan 2026'!BW26 -> 1.2614988 | E27: =IF(ISNUMBER(D27),IF(D27>0,"Naik",IF(D27<0,"Turun","Tetap")),"-") -> Naik | F27: =IFERROR(IF(ISNUMBER(D27),D27,NA()),NA()) -> 1.2614988
A28: 25 | B28: Jun 2026 - M1 | C28: 2026-06-01 s/d 2026-06-05 | D28: ='Perhitungan IPH Mingguan 2026'!BZ26 -> -1.1035301 | E28: =IF(ISNUMBER(D28),IF(D28>0,"Naik",IF(D28<0,"Turun","Tetap")),"-") -> Turun | F28: =IFERROR(IF(ISNUMBER(D28),D28,NA()),NA()) -> -1.1035301
A29: 26 | B29: Jun 2026 - M2 | C29: 2026-06-08 s/d 2026-06-12 | D29: ='Perhitungan IPH Mingguan 2026'!CC26 -> -1.5445378 | E29: =IF(ISNUMBER(D29),IF(D29>0,"Naik",IF(D29<0,"Turun","Tetap")),"-") -> Turun | F29: =IFERROR(IF(ISNUMBER(D29),D29,NA()),NA()) -> -1.5445378
A30: 27 | B30: Jun 2026 - M3 | C30: 2026-06-15 s/d 2026-06-19 | D30: ='Perhitungan IPH Mingguan 2026'!CF26 -> -1.4925761 | E30: =IF(ISNUMBER(D30),IF(D30>0,"Naik",IF(D30<0,"Turun","Tetap")),"-") -> Turun | F30: =IFERROR(IF(ISNUMBER(D30),D30,NA()),NA()) -> -1.4925761
A31: 28 | B31: Jun 2026 - M4 | C31: 2026-06-22 s/d 2026-06-26 | D31: ='Perhitungan IPH Mingguan 2026'!CI26 -> -1.9940819 | E31: =IF(ISNUMBER(D31),IF(D31>0,"Naik",IF(D31<0,"Turun","Tetap")),"-") -> Turun | F31: =IFERROR(IF(ISNUMBER(D31),D31,NA()),NA()) -> -1.9940819
A32: 29 | B32: Jun 2026 - M5 | C32: 2026-06-29 s/d 2026-06-30 | D32: ='Perhitungan IPH Mingguan 2026'!CL26 -> -2.0753592 | E32: =IF(ISNUMBER(D32),IF(D32>0,"Naik",IF(D32<0,"Turun","Tetap")),"-") -> Turun | F32: =IFERROR(IF(ISNUMBER(D32),D32,NA()),NA()) -> -2.0753592
A33: 30 | B33: Jul 2026 - M1 | C33: 2026-07-01 s/d 2026-07-03 | D33: ='Perhitungan IPH Mingguan 2026'!CO26 -> -0.66553397 | E33: =IF(ISNUMBER(D33),IF(D33>0,"Naik",IF(D33<0,"Turun","Tetap")),"-") -> Turun | F33: =IFERROR(IF(ISNUMBER(D33),D33,NA()),NA()) -> -0.66553397
A34: 31 | B34: Jul 2026 - M2 | C34: 2026-07-06 s/d 2026-07-10 | D34: ='Perhitungan IPH Mingguan 2026'!CR26 -> -0.72863384 | E34: =IF(ISNUMBER(D34),IF(D34>0,"Naik",IF(D34<0,"Turun","Tetap")),"-") -> Turun | F34: =IFERROR(IF(ISNUMBER(D34),D34,NA()),NA()) -> -0.72863384
A35: 32 | B35: Jul 2026 - M3 | C35: 2026-07-13 s/d 2026-07-17 | D35: ='Perhitungan IPH Mingguan 2026'!CU26 -> -0.72863384 | E35: =IF(ISNUMBER(D35),IF(D35>0,"Naik",IF(D35<0,"Turun","Tetap")),"-") -> Turun | F35: =IFERROR(IF(ISNUMBER(D35),D35,NA()),NA()) -> -0.72863384
A36: 33 | B36: Jul 2026 - M4 | C36: 2026-07-20 s/d 2026-07-24 | D36: ='Perhitungan IPH Mingguan 2026'!CX26 -> -0.65824272 | E36: =IF(ISNUMBER(D36),IF(D36>0,"Naik",IF(D36<0,"Turun","Tetap")),"-") -> Turun | F36: =IFERROR(IF(ISNUMBER(D36),D36,NA()),NA()) -> -0.65824272
A37: 34 | B37: Jul 2026 - M5 | C37: 2026-07-27 s/d 2026-07-31 | D37: ='Perhitungan IPH Mingguan 2026'!DA26 -> -0.39149995 | E37: =IF(ISNUMBER(D37),IF(D37>0,"Naik",IF(D37<0,"Turun","Tetap")),"-") -> Turun | F37: =IFERROR(IF(ISNUMBER(D37),D37,NA()),NA()) -> -0.39149995
A38: 35 | B38: Agu 2026 - M1 | C38: 2026-08-03 s/d 2026-08-07 | D38: ='Perhitungan IPH Mingguan 2026'!DD26 -> 0.0027917547 | E38: =IF(ISNUMBER(D38),IF(D38>0,"Naik",IF(D38<0,"Turun","Tetap")),"-") -> Naik | F38: =IFERROR(IF(ISNUMBER(D38),D38,NA()),NA()) -> 0.0027917547
A39: 36 | B39: Agu 2026 - M2 | C39: 2026-08-10 s/d 2026-08-14 | D39: ='Perhitungan IPH Mingguan 2026'!DG26 -> -0.098618657 | E39: =IF(ISNUMBER(D39),IF(D39>0,"Naik",IF(D39<0,"Turun","Tetap")),"-") -> Turun | F39: =IFERROR(IF(ISNUMBER(D39),D39,NA()),NA()) -> -0.098618657
A40: 37 | B40: Agu 2026 - M3 | C40: 2026-08-17 s/d 2026-08-21 | D40: ='Perhitungan IPH Mingguan 2026'!DJ26 -> 0.13824681 | E40: =IF(ISNUMBER(D40),IF(D40>0,"Naik",IF(D40<0,"Turun","Tetap")),"-") -> Naik | F40: =IFERROR(IF(ISNUMBER(D40),D40,NA()),NA()) -> 0.13824681
A41: 38 | B41: Agu 2026 - M4 | C41: 2026-08-24 s/d 2026-08-28 | D41: ='Perhitungan IPH Mingguan 2026'!DM26 -> 0.35800883 | E41: =IF(ISNUMBER(D41),IF(D41>0,"Naik",IF(D41<0,"Turun","Tetap")),"-") -> Naik | F41: =IFERROR(IF(ISNUMBER(D41),D41,NA()),NA()) -> 0.35800883
...

Sheet Perhitungan IPH Mingguan 2026
A1: PERHITUNGAN IPH MINGGUAN JANUARI - AGUSTUS 2026 (39 minggu) - PASAR PON JOMBANG
A2: Formula: Andil_i(Mt) = Bobot_i x [(P̄Mt,i - P̄bulan sebelumnya,i)/P̄bulan sebelumnya,i] x 100% ; Growth IPH(Mt) = Σ Andil_i(Mt). Acuan m-1 tiap minggu = rata-rata bulan kalender sebelumnya (mis. minggu2 Jan 2026 acuan = rata2 Des 2025).
D4: Jan 2026 - M1 (01-02) | G4: Jan 2026 - M2 (05-09) | J4: Jan 2026 - M3 (12-16) | M4: Jan 2026 - M4 (19-23) | P4: Jan 2026 - M5 (26-30) | S4: Feb 2026 - M1 (02-06) | V4: Feb 2026 - M2 (09-13) | Y4: Feb 2026 - M3 (16-20) | AB4: Feb 2026 - M4 (23-27) | AE4: Mar 2026 - M1 (02-06) | AH4: Mar 2026 - M2 (09-13) | AK4: Mar 2026 - M3 (16-20) | AN4: Mar 2026 - M4 (23-27) | AQ4: Mar 2026 - M5 (30-31) | AT4: Apr 2026 - M1 (01-03) | AW4: Apr 2026 - M2 (06-10) | AZ4: Apr 2026 - M3 (13-17) | BC4: Apr 2026 - M4 (20-24) | BF4: Apr 2026 - M5 (27-30) | BI4: Mei 2026 - M1 (01-01) | BL4: Mei 2026 - M2 (04-08) | BO4: Mei 2026 - M3 (11-15) | BR4: Mei 2026 - M4 (18-22) | BU4: Mei 2026 - M5 (25-29) | BX4: Jun 2026 - M1 (01-05) | CA4: Jun 2026 - M2 (08-12) | CD4: Jun 2026 - M3 (15-19) | CG4: Jun 2026 - M4 (22-26) | CJ4: Jun 2026 - M5 (29-30) | CM4: Jul 2026 - M1 (01-03) | CP4: Jul 2026 - M2 (06-10) | CS4: Jul 2026 - M3 (13-17) | CV4: Jul 2026 - M4 (20-24) | CY4: Jul 2026 - M5 (27-31) | DB4: Agu 2026 - M1 (03-07) | DE4: Agu 2026 - M2 (10-14) | DH4: Agu 2026 - M3 (17-21) | DK4: Agu 2026 - M4 (24-28) | DN4: Sep 2026 - M1 (31-04) | DQ4: Sep 2026 - M2 (07-11) | DT4: Sep 2026 - M3 (14-18) | DW4: Sep 2026 - M4 (21-25) | DZ4: Sep 2026 - M5 (28-30)
A5: No | B5: Komoditas (standar IPH) | C5: Bobot (wi) | D5: P̄ | E5: Growth% | F5: Andil% | G5: P̄ | H5: Growth% | I5: Andil% | J5: P̄ | K5: Growth% | L5: Andil% | M5: P̄ | N5: Growth% | O5: Andil% | P5: P̄ | Q5: Growth% | R5: Andil% | S5: P̄ | T5: Growth% | U5: Andil% | V5: P̄ | W5: Growth% | X5: Andil% | Y5: P̄ | Z5: Growth% | AA5: Andil% | AB5: P̄ | AC5: Growth% | AD5: Andil% | AE5: P̄ | AF5: Growth% | AG5: Andil% | AH5: P̄ | AI5: Growth% | AJ5: Andil% | AK5: P̄ | AL5: Growth% | AM5: Andil% | AN5: P̄ | AO5: Growth% | AP5: Andil% | AQ5: P̄ | AR5: Growth% | AS5: Andil% | AT5: P̄ | AU5: Growth% | AV5: Andil% | AW5: P̄ | AX5: Growth% | AY5: Andil% | AZ5: P̄ | BA5: Growth% | BB5: Andil% | BC5: P̄ | BD5: Growth% | BE5: Andil% | BF5: P̄ | BG5: Growth% | BH5: Andil% | BI5: P̄ | BJ5: Growth% | BK5: Andil% | BL5: P̄ | BM5: Growth% | BN5: Andil% | BO5: P̄ | BP5: Growth% | BQ5: Andil% | BR5: P̄ | BS5: Growth% | BT5: Andil% | BU5: P̄ | BV5: Growth% | BW5: Andil% | BX5: P̄ | BY5: Growth% | BZ5: Andil% | CA5: P̄ | CB5: Growth% | CC5: Andil% | CD5: P̄ | CE5: Growth% | CF5: Andil% | CG5: P̄ | CH5: Growth% | CI5: Andil% | CJ5: P̄ | CK5: Growth% | CL5: Andil% | CM5: P̄ | CN5: Growth% | CO5: Andil% | CP5: P̄ | CQ5: Growth% | CR5: Andil% | CS5: P̄ | CT5: Growth% | CU5: Andil% | CV5: P̄ | CW5: Growth% | CX5: Andil% | CY5: P̄ | CZ5: Growth% | DA5: Andil% | DB5: P̄ | DC5: Growth% | DD5: Andil% | DE5: P̄ | DF5: Growth% | DG5: Andil% | DH5: P̄ | DI5: Growth% | DJ5: Andil% | DK5: P̄ | DL5: Growth% | DM5: Andil% | DN5: P̄ | DO5: Growth% | DP5: Andil% | DQ5: P̄ | DR5: Growth% | DS5: Andil% | DT5: P̄ | DU5: Growth% | DV5: Andil% | DW5: P̄ | DX5: Growth% | DY5: Andil% | DZ5: P̄ | EA5: Growth% | EB5: Andil% | ED5: ABS[Jan 2026-M1] | EE5: ABS[Jan 2026-M2] | EF5: ABS[Jan 2026-M3] | EG5: ABS[Jan 2026-M4] | EH5: ABS[Jan 2026-M5] | EI5: ABS[Feb 2026-M1] | EJ5: ABS[Feb 2026-M2] | EK5: ABS[Feb 2026-M3] | EL5: ABS[Feb 2026-M4] | EM5: ABS[Mar 2026-M1] | EN5: ABS[Mar 2026-M2] | EO5: ABS[Mar 2026-M3] | EP5: ABS[Mar 2026-M4] | EQ5: ABS[Mar 2026-M5] | ER5: ABS[Apr 2026-M1] | ES5: ABS[Apr 2026-M2] | ET5: ABS[Apr 2026-M3] | EU5: ABS[Apr 2026-M4] | EV5: ABS[Apr 2026-M5] | EW5: ABS[Mei 2026-M1] | EX5: ABS[Mei 2026-M2] | EY5: ABS[Mei 2026-M3] | EZ5: ABS[Mei 2026-M4] | FA5: ABS[Mei 2026-M5] | FB5: ABS[Jun 2026-M1] | FC5: ABS[Jun 2026-M2] | FD5: ABS[Jun 2026-M3] | FE5: ABS[Jun 2026-M4] | FF5: ABS[Jun 2026-M5] | FG5: ABS[Jul 2026-M1] | FH5: ABS[Jul 2026-M2] | FI5: ABS[Jul 2026-M3] | FJ5: ABS[Jul 2026-M4] | FK5: ABS[Jul 2026-M5] | FL5: ABS[Agu 2026-M1] | FM5: ABS[Agu 2026-M2] | FN5: ABS[Agu 2026-M3] | FO5: ABS[Agu 2026-M4] | FP5: ABS[Agu 2026-M5] | FQ5: ABS[Sep 2026-M1] | FR5: ABS[Sep 2026-M2] | FS5: ABS[Sep 2026-M3] | FT5: ABS[Sep 2026-M4] | FU5: ABS[Sep 2026-M5]
A6: 1 | B6: beras 1111001 | C6: ='P0Q0 Dasar 2022'!F5 -> 0.12508906 | D6: =IFERROR(AVERAGEIF('Pemetaan Variant'!$A$5:$A$32,$B6,'Pemetaan Variant'!$L$5:$L$32),"n/a") -> 13000 | E6: =IFERROR(IF(ISNUMBER(D6),(D6-AVERAGEIF('Pemetaan Variant'!$A$5:$A$32,$B6,'Pemetaan Variant'!$D$5:$D$32))/AVERAGEIF('Pemetaan Variant'!$A$5:$A$32,$B6,'Pemetaan Variant'!$D$5:$D$32)*100,"n/a"),"n/a") -> 0 | F6: =IFERROR(IF(ISNUMBER(E6),$C6*E6,"n/a"),"n/a") -> 0 | G6: =IFERROR(AVERAGEIF('Pemetaan Variant'!$A$5:$A$32,$B6,'Pemetaan Variant'!$M$5:$M$32),"n/a") -> 13000 | H6: =IFERROR(IF(ISNUMBER(G6),(G6-AVERAGEIF('Pemetaan Variant'!$A$5:$A$32,$B6,'Pemetaan Variant'!$D$5:$D$32))/AVERAGEIF('Pemetaan Variant'!$A$5:$A$32,$B6,'Pemetaan Variant'!$D$5:$D$32)*100,"n/a"),"n/a") -> 0 | I6: =IFERROR(IF(ISNUMBER(H6),$C6*H6,"n/a"),"n/a") -> 0 | J6: =IFERROR(AVERAGEIF('Pemetaan Variant'!$A$5:$A$32,$B6,'Pemetaan Variant'!$N$5:$N$32),"n/a") -> 13000 | K6: =IFERROR(IF(ISNUMBER(J6),(J6-AVERAGEIF('Pemetaan Variant'!$A$5:$A$32,$B6,'Pemetaan Variant'!$D$5:$D$32))/AVERAGEIF('Pemetaan Variant'!$A$5:$A$32,$B6,'Pemetaan Variant'!$D$5:$D$32)*100,"n/a"),"n/a") -> 0 | L6: =IFERROR(IF(ISNUMBER(K6),$C6*K6,"n/a"),"n/a") -> 0 | M6: =IFERROR(AVERAGEIF('Pemetaan Variant'!$A$5:$A$32,$B6,'Pemetaan Variant'!$O$5:$O$32),"n/a") -> 13000 | N6: =IFERROR(IF(ISNUMBER(M6),(M6-AVERAGEIF('Pemetaan Variant'!$A$5:$A$32,$B6,'Pemetaan Variant'!$D$5:$D$32))/AVERAGEIF('Pemetaan Variant'!$A$5:$A$32,$B6,'Pemetaan Variant'!$D$5:$D$32)*100,"n/a"),"n/a") -> 0 | O6: =IFERROR(IF(ISNUMBER(N6),$C6*N6,"n/a"),"n/a") -> 0 | P6: =IFERROR(AVERAGEIF('Pemetaan Variant'!$A$5:$A$32,$B6,'Pemetaan Variant'!$P$5:$P$32),"n/a") -> 13000 | Q6: =IFERROR(IF(ISNUMBER(P6),(P6-AVERAGEIF('Pemetaan Variant'!$A$5:$A$32,$B6,'Pemetaan Variant'!$D$5:$D$32))/AVERAGEIF('Pemetaan Variant'!$A$5:$A$32,$B6,'Pemetaan Variant'!$D$5:$D$32)*100,"n/a"),"n/a") -> 0 | R6: =IFERROR(IF(ISNUMBER(Q6),$C6*Q6,"n/a"),"n/a") -> 0 | S6: =IFERROR(AVERAGEIF('Pemetaan Variant'!$A$5:$A$32,$B6,'Pemetaan Variant'!$Q$5:$Q$32),"n/a") -> 13000 | T6: =IFERROR(IF(ISNUMBER(S6),(S6-AVERAGEIF('Pemetaan Variant'!$A$5:$A$32,$B6,'Pemetaan Variant'!$E$5:$E$32))/AVERAGEIF('Pemetaan Variant'!$A$5:$A$32,$B6,'Pemetaan Variant'!$E$5:$E$32)*100,"n/a"),"n/a") -> 0 | U6: =IFERROR(IF(ISNUMBER(T6),$C6*T6,"n/a"),"n/a") -> 0 | V6: =IFERROR(AVERAGEIF('Pemetaan Variant'!$A$5:$A$32,$B6,'Pemetaan Variant'!$R$5:$R$32),"n/a") -> 13000 | W6: =IFERROR(IF(ISNUMBER(V6),(V6-AVERAGEIF('Pemetaan Variant'!$A$5:$A$32,$B6,'Pemetaan Variant'!$E$5:$E$32))/AVERAGEIF('Pemetaan Variant'!$A$5:$A$32,$B6,'Pemetaan Variant'!$E$5:$E$32)*100,"n/a"),"n/a") -> 0 | X6: =IFERROR(IF(ISNUMBER(W6),$C6*W6,"n/a"),"n/a") -> 0 | Y6: =IFERROR(AVERAGEIF('Pemetaan Variant'!$A$5:$A$32,$B6,'Pemetaan Variant'!$S$5:$S$32),"n/a") -> 13000 | Z6: =IFERROR(IF(ISNUMBER(Y6),(Y6-AVERAGEIF('Pemetaan Variant'!$A$5:$A$32,$B6,'Pemetaan Variant'!$E$5:$E$32))/AVERAGEIF('Pemetaan Variant'!$A$5:$A$32,$B6,'Pemetaan Variant'!$E$5:$E$32)*100,"n/a"),"n/a") -> 0 | AA6: =IFERROR(IF(ISNUMBER(Z6),$C6*Z6,"n/a"),"n/a") -> 0 | AB6: =IFERROR(AVERAGEIF('Pemetaan Variant'!$A$5:$A$32,$B6,'Pemetaan Variant'!$T$5:$T$32),"n/a") -> 13000 | AC6: =IFERROR(IF(ISNUMBER(AB6),(AB6-AVERAGEIF('Pemetaan Variant'!$A$5:$A$32,$B6,'Pemetaan Variant'!$E$5:$E$32))/AVERAGEIF('Pemetaan Variant'!$A$5:$A$32,$B6,'Pemetaan Variant'!$E$5:$E$32)*100,"n/a"),"n/a") -> 0 | AD6: =IFERROR(IF(ISNUMBER(AC6),$C6*AC6,"n/a"),"n/a") -> 0 | AE6: =IFERROR(AVERAGEIF('Pemetaan Variant'!$A$5:$A$32,$B6,'Pemetaan Variant'!$U$5:$U$32),"n/a") -> 13000 | AF6: =IFERROR(IF(ISNUMBER(AE6),(AE6-AVERAGEIF('Pemetaan Variant'!$A$5:$A$32,$B6,'Pemetaan Variant'!$F$5:$F$32))/AVERAGEIF('Pemetaan Variant'!$A$5:$A$32,$B6,'Pemetaan Variant'!$F$5:$F$32)*100,"n/a"),"n/a") -> 0 | AG6: =IFERROR(IF(ISNUMBER(AF6),$C6*AF6,"n/a"),"n/a") -> 0 | AH6: =IFERROR(AVERAGEIF('Pemetaan Variant'!$A$5:$A$32,$B6,'Pemetaan Variant'!$V$5:$V$32),"n/a") -> 13000 | AI6: =IFERROR(IF(ISNUMBER(AH6),(AH6-AVERAGEIF('Pemetaan Variant'!$A$5:$A$32,$B6,'Pemetaan Variant'!$F$5:$F$32))/AVERAGEIF('Pemetaan Variant'!$A$5:$A$32,$B6,'Pemetaan Variant'!$F$5:$F$32)*100,"n/a"),"n/a") -> 0 | AJ6: =IFERROR(IF(ISNUMBER(AI6),$C6*AI6,"n/a"),"n/a") -> 0 | AK6: =IFERROR(AVERAGEIF('Pemetaan Variant'!$A$5:$A$32,$B6,'Pemetaan Variant'!$W$5:$W$32),"n/a") -> 13000 | AL6: =IFERROR(IF(ISNUMBER(AK6),(AK6-AVERAGEIF('Pemetaan Variant'!$A$5:$A$32,$B6,'Pemetaan Variant'!$F$5:$F$32))/AVERAGEIF('Pemetaan Variant'!$A$5:$A$32,$B6,'Pemetaan Variant'!$F$5:$F$32)*100,"n/a"),"n/a") -> 0 | AM6: =IFERROR(IF(ISNUMBER(AL6),$C6*AL6,"n/a"),"n/a") -> 0 | AN6: =IFERROR(AVERAGEIF('Pemetaan Variant'!$A$5:$A$32,$B6,'Pemetaan Variant'!$X$5:$X$32),"n/a") -> 13000 | AO6: =IFERROR(IF(ISNUMBER(AN6),(AN6-AVERAGEIF('Pemetaan Variant'!$A$5:$A$32,$B6,'Pemetaan Variant'!$F$5:$F$32))/AVERAGEIF('Pemetaan Variant'!$A$5:$A$32,$B6,'Pemetaan Variant'!$F$5:$F$32)*100,"n/a"),"n/a") -> 0 | AP6: =IFERROR(IF(ISNUMBER(AO6),$C6*AO6,"n/a"),"n/a") -> 0 | AQ6: =IFERROR(AVERAGEIF('Pemetaan Variant'!$A$5:$A$32,$B6,'Pemetaan Variant'!$Y$5:$Y$32),"n/a") -> 13000 | AR6: =IFERROR(IF(ISNUMBER(AQ6),(AQ6-AVERAGEIF('Pemetaan Variant'!$A$5:$A$32,$B6,'Pemetaan Variant'!$F$5:$F$32))/AVERAGEIF('Pemetaan Variant'!$A$5:$A$32,$B6,'Pemetaan Variant'!$F$5:$F$32)*100,"n/a"),"n/a") -> 0 | AS6: =IFERROR(IF(ISNUMBER(AR6),$C6*AR6,"n/a"),"n/a") -> 0 | AT6: =IFERROR(AVERAGEIF('Pemetaan Variant'!$A$5:$A$32,$B6,'Pemetaan Variant'!$Z$5:$Z$32),"n/a") -> 13000 | AU6: =IFERROR(IF(ISNUMBER(AT6),(AT6-AVERAGEIF('Pemetaan Variant'!$A$5:$A$32,$B6,'Pemetaan Variant'!$G$5:$G$32))/AVERAGEIF('Pemetaan Variant'!$A$5:$A$32,$B6,'Pemetaan Variant'!$G$5:$G$32)*100,"n/a"),"n/a") -> 0 | AV6: =IFERROR(IF(ISNUMBER(AU6),$C6*AU6,"n/a"),"n/a") -> 0 | AW6: =IFERROR(AVERAGEIF('Pemetaan Variant'!$A$5:$A$32,$B6,'Pemetaan Variant'!$AA$5:$AA$32),"n/a") -> 13000 | AX6: =IFERROR(IF(ISNUMBER(AW6),(AW6-AVERAGEIF('Pemetaan Variant'!$A$5:$A$32,$B6,'Pemetaan Variant'!$G$5:$G$32))/AVERAGEIF('Pemetaan Variant'!$A$5:$A$32,$B6,'Pemetaan Variant'!$G$5:$G$32)*100,"n/a"),"n/a") -> 0 | AY6: =IFERROR(IF(ISNUMBER(AX6),$C6*AX6,"n/a"),"n/a") -> 0 | AZ6: =IFERROR(AVERAGEIF('Pemetaan Variant'!$A$5:$A$32,$B6,'Pemetaan Variant'!$AB$5:$AB$32),"n/a") -> 13000 | BA6: =IFERROR(IF(ISNUMBER(AZ6),(AZ6-AVERAGEIF('Pemetaan Variant'!$A$5:$A$32,$B6,'Pemetaan Variant'!$G$5:$G$32))/AVERAGEIF('Pemetaan Variant'!$A$5:$A$32,$B6,'Pemetaan Variant'!$G$5:$G$32)*100,"n/a"),"n/a") -> 0 | BB6: =IFERROR(IF(ISNUMBER(BA6),$C6*BA6,"n/a"),"n/a") -> 0 | BC6: =IFERROR(AVERAGEIF('Pemetaan Variant'!$A$5:$A$32,$B6,'Pemetaan Variant'!$AC$5:$AC$32),"n/a") -> 13633.333 | BD6: =IFERROR(IF(ISNUMBER(BC6),(BC6-AVERAGEIF('Pemetaan Variant'!$A$5:$A$32,$B6,'Pemetaan Variant'!$G$5:$G$32))/AVERAGEIF('Pemetaan Variant'!$A$5:$A$32,$B6,'Pemetaan Variant'!$G$5:$G$32)*100,"n/a"),"n/a") -> 4.8717949 | BE6: =IFERROR(IF(ISNUMBER(BD6),$C6*BD6,"n/a"),"n/a") -> 0.60940823 | BF6: =IFERROR(AVERAGEIF('Pemetaan Variant'!$A$5:$A$32,$B6,'Pemetaan Variant'!$AD$5:$AD$32),"n/a") -> 13633.333 | BG6: =IFERROR(IF(ISNUMBER(BF6),(BF6-AVERAGEIF('Pemetaan Variant'!$A$5:$A$32,$B6,'Pemetaan Variant'!$G$5:$G$32))/AVERAGEIF('Pemetaan Variant'!$A$5:$A$32,$B6,'Pemetaan Variant'!$G$5:$G$32)*100,"n/a"),"n/a") -> 4.8717949 | BH6: =IFERROR(IF(ISNUMBER(BG6),$C6*BG6,"n/a"),"n/a") -> 0.60940823 | BI6: =IFERROR(AVERAGEIF('Pemetaan Variant'!$A$5:$A$32,$B6,'Pemetaan Variant'!$AE$5:$AE$32),"n/a") -> n/a | BJ6: =IFERROR(IF(ISNUMBER(BI6),(BI6-AVERAGEIF('Pemetaan Variant'!$A$5:$A$32,$B6,'Pemetaan Variant'!$H$5:$H$32))/AVERAGEIF('Pemetaan Variant'!$A$5:$A$32,$B6,'Pemetaan Variant'!$H$5:$H$32)*100,"n/a"),"n/a") -> n/a | BK6: =IFERROR(IF(ISNUMBER(BJ6),$C6*BJ6,"n/a"),"n/a") -> n/a | BL6: =IFERROR(AVERAGEIF('Pemetaan Variant'!$A$5:$A$32,$B6,'Pemetaan Variant'!$AF$5:$AF$32),"n/a") -> 13633.333 | BM6: =IFERROR(IF(ISNUMBER(BL6),(BL6-AVERAGEIF('Pemetaan Variant'!$A$5:$A$32,$B6,'Pemetaan Variant'!$H$5:$H$32))/AVERAGEIF('Pemetaan Variant'!$A$5:$A$32,$B6,'Pemetaan Variant'!$H$5:$H$32)*100,"n/a"),"n/a") -> 2.7269465 | BN6: =IFERROR(IF(ISNUMBER(BM6),$C6*BM6,"n/a"),"n/a") -> 0.34111117 | BO6: =IFERROR(AVERAGEIF('Pemetaan Variant'!$A$5:$A$32,$B6,'Pemetaan Variant'!$AG$5:$AG$32),"n/a") -> 13608.333 | BP6: =IFERROR(IF(ISNUMBER(BO6),(BO6-AVERAGEIF('Pemetaan Variant'!$A$5:$A$32,$B6,'Pemetaan Variant'!$H$5:$H$32))/AVERAGEIF('Pemetaan Variant'!$A$5:$A$32,$B6,'Pemetaan Variant'!$H$5:$H$32)*100,"n/a"),"n/a") -> 2.5385719 | BQ6: =IFERROR(IF(ISNUMBER(BP6),$C6*BP6,"n/a"),"n/a") -> 0.31754757 | BR6: =IFERROR(AVERAGEIF('Pemetaan Variant'!$A$5:$A$32,$B6,'Pemetaan Variant'!$AH$5:$AH$32),"n/a") -> 13586.667 | BS6: =IFERROR(IF(ISNUMBER(BR6),(BR6-AVERAGEIF('Pemetaan Variant'!$A$5:$A$32,$B6,'Pemetaan Variant'!$H$5:$H$32))/AVERAGEIF('Pemetaan Variant'!$A$5:$A$32,$B6,'Pemetaan Variant'!$H$5:$H$32)*100,"n/a"),"n/a") -> 2.375314 | BT6: =IFERROR(IF(ISNUMBER(BS6),$C6*BS6,"n/a"),"n/a") -> 0.29712578 | BU6: =IFERROR(AVERAGEIF('Pemetaan Variant'!$A$5:$A$32,$B6,'Pemetaan Variant'!$AI$5:$AI$32),"n/a") -> 13233.333 | BV6: =IFERROR(IF(ISNUMBER(BU6),(BU6-AVERAGEIF('Pemetaan Variant'!$A$5:$A$32,$B6,'Pemetaan Variant'!$H$5:$H$32))/AVERAGEIF('Pemetaan Variant'!$A$5:$A$32,$B6,'Pemetaan Variant'!$H$5:$H$32)*100,"n/a"),"n/a") -> -0.287047 | BW6: =IFERROR(IF(ISNUMBER(BV6),$C6*BV6,"n/a"),"n/a") -> -0.035906439 | BX6: =IFERROR(AVERAGEIF('Pemetaan Variant'!$A$5:$A$32,$B6,'Pemetaan Variant'!$AJ$5:$AJ$32),"n/a") -> 12933.333 | BY6: =IFERROR(IF(ISNUMBER(BX6),(BX6-AVERAGEIF('Pemetaan Variant'!$A$5:$A$32,$B6,'Pemetaan Variant'!$I$5:$I$32))/AVERAGEIF('Pemetaan Variant'!$A$5:$A$32,$B6,'Pemetaan Variant'!$I$5:$I$32)*100,"n/a"),"n/a") -> -4.4739373 | BZ6: =IFERROR(IF(ISNUMBER(BY6),$C6*BY6,"n/a"),"n/a") -> -0.5596406 | CA6: =IFERROR(AVERAGEIF('Pemetaan Variant'!$A$5:$A$32,$B6,'Pemetaan Variant'!$AK$5:$AK$32),"n/a") -> 12860 | CB6: =IFERROR(IF(ISNUMBER(CA6),(CA6-AVERAGEIF('Pemetaan Variant'!$A$5:$A$32,$B6,'Pemetaan Variant'!$I$5:$I$32))/AVERAGEIF('Pemetaan Variant'!$A$5:$A$32,$B6,'Pemetaan Variant'!$I$5:$I$32)*100,"n/a"),"n/a") -> -5.0155799 | CC6: =IFERROR(IF(ISNUMBER(CB6),$C6*CB6,"n/a"),"n/a") -> -0.62739416 | CD6: =IFERROR(AVERAGEIF('Pemetaan Variant'!$A$5:$A$32,$B6,'Pemetaan Variant'!$AL$5:$AL$32),"n/a") -> 12925 | CE6: =IFERROR(IF(ISNUMBER(CD6),(CD6-AVERAGEIF('Pemetaan Variant'!$A$5:$A$32,$B6,'Pemetaan Variant'!$I$5:$I$32))/AVERAGEIF('Pemetaan Variant'!$A$5:$A$32,$B6,'Pemetaan Variant'!$I$5:$I$32)*100,"n/a"),"n/a") -> -4.5354876 | CF6: =IFERROR(IF(ISNUMBER(CE6),$C6*CE6,"n/a"),"n/a") -> -0.56733987 | CG6: =IFERROR(AVERAGEIF('Pemetaan Variant'!$A$5:$A$32,$B6,'Pemetaan Variant'!$AM$5:$AM$32),"n/a") -> 12866.667 | CH6: =IFERROR(IF(ISNUMBER(CG6),(CG6-AVERAGEIF('Pemetaan Variant'!$A$5:$A$32,$B6,'Pemetaan Variant'!$I$5:$I$32))/AVERAGEIF('Pemetaan Variant'!$A$5:$A$32,$B6,'Pemetaan Variant'!$I$5:$I$32)*100,"n/a"),"n/a") -> -4.9663397 | CI6: =IFERROR(IF(ISNUMBER(CH6),$C6*CH6,"n/a"),"n/a") -> -0.62123475 | CJ6: =IFERROR(AVERAGEIF('Pemetaan Variant'!$A$5:$A$32,$B6,'Pemetaan Variant'!$AN$5:$AN$32),"n/a") -> 12866.667 | CK6: =IFERROR(IF(ISNUMBER(CJ6),(CJ6-AVERAGEIF('Pemetaan Variant'!$A$5:$A$32,$B6,'Pemetaan Variant'!$I$5:$I$32))/AVERAGEIF('Pemetaan Variant'!$A$5:$A$32,$B6,'Pemetaan Variant'!$I$5:$I$32)*100,"n/a"),"n/a") -> -4.9663397 | CL6: =IFERROR(IF(ISNUMBER(CK6),$C6*CK6,"n/a"),"n/a") -> -0.62123475 | CM6: =IFERROR(AVERAGEIF('Pemetaan Variant'!$A$5:$A$32,$B6,'Pemetaan Variant'!$AO$5:$AO$32),"n/a") -> 12866.667 | CN6: =IFERROR(IF(ISNUMBER(CM6),(CM6-AVERAGEIF('Pemetaan Variant'!$A$5:$A$32,$B6,'Pemetaan Variant'!$J$5:$J$32))/AVERAGEIF('Pemetaan Variant'!$A$5:$A$32,$B6,'Pemetaan Variant'!$J$5:$J$32)*100,"n/a"),"n/a") -> -0.18101888 | CO6: =IFERROR(IF(ISNUMBER(CN6),$C6*CN6,"n/a"),"n/a") -> -0.022643481 | CP6: =IFERROR(AVERAGEIF('Pemetaan Variant'!$A$5:$A$32,$B6,'Pemetaan Variant'!$AP$5:$AP$32),"n/a") -> 12866.667 | CQ6: =IFERROR(IF(ISNUMBER(CP6),(CP6-AVERAGEIF('Pemetaan Variant'!$A$5:$A$32,$B6,'Pemetaan Variant'!$J$5:$J$32))/AVERAGEIF('Pemetaan Variant'!$A$5:$A$32,$B6,'Pemetaan Variant'!$J$5:$J$32)*100,"n/a"),"n/a") -> -0.18101888 | CR6: =IFERROR(IF(ISNUMBER(CQ6),$C6*CQ6,"n/a"),"n/a") -> -0.022643481 | CS6: =IFERROR(AVERAGEIF('Pemetaan Variant'!$A$5:$A$32,$B6,'Pemetaan Variant'!$AQ$5:$AQ$32),"n/a") -> 12866.667 | CT6: =IFERROR(IF(ISNUMBER(CS6),(CS6-AVERAGEIF('Pemetaan Variant'!$A$5:$A$32,$B6,'Pemetaan Variant'!$J$5:$J$32))/AVERAGEIF('Pemetaan Variant'!$A$5:$A$32,$B6,'Pemetaan Variant'!$J$5:$J$32)*100,"n/a"),"n/a") -> -0.18101888 | CU6: =IFERROR(IF(ISNUMBER(CT6),$C6*CT6,"n/a"),"n/a") -> -0.022643481 | CV6: =IFERROR(AVERAGEIF('Pemetaan Variant'!$A$5:$A$32,$B6,'Pemetaan Variant'!$AR$5:$AR$32),"n/a") -> 12866.667 | CW6: =IFERROR(IF(ISNUMBER(CV6),(CV6-AVERAGEIF('Pemetaan Variant'!$A$5:$A$32,$B6,'Pemetaan Variant'!$J$5:$J$32))/AVERAGEIF('Pemetaan Variant'!$A$5:$A$32,$B6,'Pemetaan Variant'!$J$5:$J$32)*100,"n/a"),"n/a") -> -0.18101888 | CX6: =IFERROR(IF(ISNUMBER(CW6),$C6*CW6,"n/a"),"n/a") -> -0.022643481 | CY6: =IFERROR(AVERAGEIF('Pemetaan Variant'!$A$5:$A$32,$B6,'Pemetaan Variant'!$AS$5:$AS$32),"n/a") -> 12866.667 | CZ6: =IFERROR(IF(ISNUMBER(CY6),(CY6-AVERAGEIF('Pemetaan Variant'!$A$5:$A$32,$B6,'Pemetaan Variant'!$J$5:$J$32))/AVERAGEIF('Pemetaan Variant'!$A$5:$A$32,$B6,'Pemetaan Variant'!$J$5:$J$32)*100,"n/a"),"n/a") -> -0.18101888 | DA6: =IFERROR(IF(ISNUMBER(CZ6),$C6*CZ6,"n/a"),"n/a") -> -0.022643481 | DB6: =IFERROR(AVERAGEIF('Pemetaan Variant'!$A$5:$A$32,$B6,'Pemetaan Variant'!$AT$5:$AT$32),"n/a") -> 12866.667 | DC6: =IFERROR(IF(ISNUMBER(DB6),(DB6-AVERAGEIF('Pemetaan Variant'!$A$5:$A$32,$B6,'Pemetaan Variant'!$K$5:$K$32))/AVERAGEIF('Pemetaan Variant'!$A$5:$A$32,$B6,'Pemetaan Variant'!$K$5:$K$32)*100,"n/a"),"n/a") -> 0 | DD6: =IFERROR(IF(ISNUMBER(DC6),$C6*DC6,"n/a"),"n/a") -> 0 | DE6: =IFERROR(AVERAGEIF('Pemetaan Variant'!$A$5:$A$32,$B6,'Pemetaan Variant'!$AU$5:$AU$32),"n/a") -> 12866.667 | DF6: =IFERROR(IF(ISNUMBER(DE6),(DE6-AVERAGEIF('Pemetaan Variant'!$A$5:$A$32,$B6,'Pemetaan Variant'!$K$5:$K$32))/AVERAGEIF('Pemetaan Variant'!$A$5:$A$32,$B6,'Pemetaan Variant'!$K$5:$K$32)*100,"n/a"),"n/a") -> 0 | DG6: =IFERROR(IF(ISNUMBER(DF6),$C6*DF6,"n/a"),"n/a") -> 0 | DH6: =IFERROR(AVERAGEIF('Pemetaan Variant'!$A$5:$A$32,$B6,'Pemetaan Variant'!$AV$5:$AV$32),"n/a") -> 12866.667 | DI6: =IFERROR(IF(ISNUMBER(DH6),(DH6-AVERAGEIF('Pemetaan Variant'!$A$5:$A$32,$B6,'Pemetaan Variant'!$K$5:$K$32))/AVERAGEIF('Pemetaan Variant'!$A$5:$A$32,$B6,'Pemetaan Variant'!$K$5:$K$32)*100,"n/a"),"n/a") -> 0 | DJ6: =IFERROR(IF(ISNUMBER(DI6),$C6*DI6,"n/a"),"n/a") -> 0 | DK6: =IFERROR(AVERAGEIF('Pemetaan Variant'!$A$5:$A$32,$B6,'Pemetaan Variant'!$AW$5:$AW$32),"n/a") -> 12879.167 | DL6: =IFERROR(IF(ISNUMBER(DK6),(DK6-AVERAGEIF('Pemetaan Variant'!$A$5:$A$32,$B6,'Pemetaan Variant'!$K$5:$K$32))/AVERAGEIF('Pemetaan Variant'!$A$5:$A$32,$B6,'Pemetaan Variant'!$K$5:$K$32)*100,"n/a"),"n/a") -> 0.097150259 | DM6: =IFERROR(IF(ISNUMBER(DL6),$C6*DL6,"n/a"),"n/a") -> 0.012152434 | DN6: =IFERROR(AVERAGEIF('Pemetaan Variant'!$A$5:$A$32,$B6,'Pemetaan Variant'!$AZ$5:$AZ$32),"n/a") -> 12883.333 | DO6: =IFERROR(IF(ISNUMBER(DN6),(DN6-AVERAGEIF('Pemetaan Variant'!$A$5:$A$32,$B6,'Pemetaan Variant'!$AY$5:$AY$32))/AVERAGEIF('Pemetaan Variant'!$A$5:$A$32,$B6,'Pemetaan Variant'!$AY$5:$AY$32)*100,"n/a"),"n/a") -> 0.10792143 | DP6: =IFERROR(IF(ISNUMBER(DO6),$C6*DO6,"n/a"),"n/a") -> 0.01349979 | DQ6: =IFERROR(AVERAGEIF('Pemetaan Variant'!$A$5:$A$32,$B6,'Pemetaan Variant'!$BA$5:$BA$32),"n/a") -> n/a | DR6: =IFERROR(IF(ISNUMBER(DQ6),(DQ6-AVERAGEIF('Pemetaan Variant'!$A$5:$A$32,$B6,'Pemetaan Variant'!$AY$5:$AY$32))/AVERAGEIF('Pemetaan Variant'!$A$5:$A$32,$B6,'Pemetaan Variant'!$AY$5:$AY$32)*100,"n/a"),"n/a") -> n/a | DS6: =IFERROR(IF(ISNUMBER(DR6),$C6*DR6,"n/a"),"n/a") -> n/a | DT6: =IFERROR(AVERAGEIF('Pemetaan Variant'!$A$5:$A$32,$B6,'Pemetaan Variant'!$BB$5:$BB$32),"n/a") -> n/a | DU6: =IFERROR(IF(ISNUMBER(DT6),(DT6-AVERAGEIF('Pemetaan Variant'!$A$5:$A$32,$B6,'Pemetaan Variant'!$AY$5:$AY$32))/AVERAGEIF('Pemetaan Variant'!$A$5:$A$32,$B6,'Pemetaan Variant'!$AY$5:$AY$32)*100,"n/a"),"n/a") -> n/a | DV6: =IFERROR(IF(ISNUMBER(DU6),$C6*DU6,"n/a"),"n/a") -> n/a | DW6: =IFERROR(AVERAGEIF('Pemetaan Variant'!$A$5:$A$32,$B6,'Pemetaan Variant'!$BC$5:$BC$32),"n/a") -> n/a | DX6: =IFERROR(IF(ISNUMBER(DW6),(DW6-AVERAGEIF('Pemetaan Variant'!$A$5:$A$32,$B6,'Pemetaan Variant'!$AY$5:$AY$32))/AVERAGEIF('Pemetaan Variant'!$A$5:$A$32,$B6,'Pemetaan Variant'!$AY$5:$AY$32)*100,"n/a"),"n/a") -> n/a | DY6: =IFERROR(IF(ISNUMBER(DX6),$C6*DX6,"n/a"),"n/a") -> n/a | DZ6: =IFERROR(AVERAGEIF('Pemetaan Variant'!$A$5:$A$32,$B6,'Pemetaan Variant'!$BD$5:$BD$32),"n/a") -> n/a | EA6: =IFERROR(IF(ISNUMBER(DZ6),(DZ6-AVERAGEIF('Pemetaan Variant'!$A$5:$A$32,$B6,'Pemetaan Variant'!$AY$5:$AY$32))/AVERAGEIF('Pemetaan Variant'!$A$5:$A$32,$B6,'Pemetaan Variant'!$AY$5:$AY$32)*100,"n/a"),"n/a") -> n/a | EB6: =IFERROR(IF(ISNUMBER(EA6),$C6*EA6,"n/a"),"n/a") -> n/a | ED6: =IFERROR(ABS(F6),0) -> 0 | EE6: =IFERROR(ABS(I6),0) -> 0 | EF6: =IFERROR(ABS(L6),0) -> 0 | EG6: =IFERROR(ABS(O6),0) -> 0 | EH6: =IFERROR(ABS(R6),0) -> 0 | EI6: =IFERROR(ABS(U6),0) -> 0 | EJ6: =IFERROR(ABS(X6),0) -> 0 | EK6: =IFERROR(ABS(AA6),0) -> 0 | EL6: =IFERROR(ABS(AD6),0) -> 0 | EM6: =IFERROR(ABS(AG6),0) -> 0 | EN6: =IFERROR(ABS(AJ6),0) -> 0 | EO6: =IFERROR(ABS(AM6),0) -> 0 | EP6: =IFERROR(ABS(AP6),0) -> 0 | EQ6: =IFERROR(ABS(AS6),0) -> 0 | ER6: =IFERROR(ABS(AV6),0) -> 0 | ES6: =IFERROR(ABS(AY6),0) -> 0 | ET6: =IFERROR(ABS(BB6),0) -> 0 | EU6: =IFERROR(ABS(BE6),0) -> 0.60940823 | EV6: =IFERROR(ABS(BH6),0) -> 0.60940823 | EW6: =IFERROR(ABS(BK6),0) -> 0 | EX6: =IFERROR(ABS(BN6),0) -> 0.34111117 | EY6: =IFERROR(ABS(BQ6),0) -> 0.31754757 | EZ6: =IFERROR(ABS(BT6),0) -> 0.29712578 | FA6: =IFERROR(ABS(BW6),0) -> 0.035906439 | FB6: =IFERROR(ABS(BZ6),0) -> 0.5596406 | FC6: =IFERROR(ABS(CC6),0) -> 0.62739416 | FD6: =IFERROR(ABS(CF6),0) -> 0.56733987 | FE6: =IFERROR(ABS(CI6),0) -> 0.62123475 | FF6: =IFERROR(ABS(CL6),0) -> 0.62123475 | FG6: =IFERROR(ABS(CO6),0) -> 0.022643481 | FH6: =IFERROR(ABS(CR6),0) -> 0.022643481 | FI6: =IFERROR(ABS(CU6),0) -> 0.022643481 | FJ6: =IFERROR(ABS(CX6),0) -> 0.022643481 | FK6: =IFERROR(ABS(DA6),0) -> 0.022643481 | FL6: =IFERROR(ABS(DD6),0) -> 0 | FM6: =IFERROR(ABS(DG6),0) -> 0 | FN6: =IFERROR(ABS(DJ6),0) -> 0 | FO6: =IFERROR(ABS(DM6),0) -> 0.012152434 | FP6: =IFERROR(ABS(#REF!),0) -> 0 | FQ6: =IFERROR(ABS(DP6),0) -> 0.01349979 | FR6: =IFERROR(ABS(DS6),0) -> 0 | FS6: =IFERROR(ABS(DV6),0) -> 0 | FT6: =IFERROR(ABS(DY6),0) -> 0 | FU6: =IFERROR(ABS(EB6),0) -> 0
A7: 2 | B7: tepung terigu 01115005 | C7: ='P0Q0 Dasar 2022'!F6 -> 0.0079366405 | D7: =IFERROR(AVERAGEIF('Pemetaan Variant'!$A$5:$A$32,$B7,'Pemetaan Variant'!$L$5:$L$32),"n/a") -> 11000 | E7: =IFERROR(IF(ISNUMBER(D7),(D7-AVERAGEIF('Pemetaan Variant'!$A$5:$A$32,$B7,'Pemetaan Variant'!$D$5:$D$32))/AVERAGEIF('Pemetaan Variant'!$A$5:$A$32,$B7,'Pemetaan Variant'!$D$5:$D$32)*100,"n/a"),"n/a") -> 0 | F7: =IFERROR(IF(ISNUMBER(E7),$C7*E7,"n/a"),"n/a") -> 0 | G7: =IFERROR(AVERAGEIF('Pemetaan Variant'!$A$5:$A$32,$B7,'Pemetaan Variant'!$M$5:$M$32),"n/a") -> 11000 | H7: =IFERROR(IF(ISNUMBER(G7),(G7-AVERAGEIF('Pemetaan Variant'!$A$5:$A$32,$B7,'Pemetaan Variant'!$D$5:$D$32))/AVERAGEIF('Pemetaan Variant'!$A$5:$A$32,$B7,'Pemetaan Variant'!$D$5:$D$32)*100,"n/a"),"n/a") -> 0 | I7: =IFERROR(IF(ISNUMBER(H7),$C7*H7,"n/a"),"n/a") -> 0 | J7: =IFERROR(AVERAGEIF('Pemetaan Variant'!$A$5:$A$32,$B7,'Pemetaan Variant'!$N$5:$N$32),"n/a") -> 11000 | K7: =IFERROR(IF(ISNUMBER(J7),(J7-AVERAGEIF('Pemetaan Variant'!$A$5:$A$32,$B7,'Pemetaan Variant'!$D$5:$D$32))/AVERAGEIF('Pemetaan Variant'!$A$5:$A$32,$B7,'Pemetaan Variant'!$D$5:$D$32)*100,"n/a"),"n/a") -> 0 | L7: =IFERROR(IF(ISNUMBER(K7),$C7*K7,"n/a"),"n/a") -> 0 | M7: =IFERROR(AVERAGEIF('Pemetaan Variant'!$A$5:$A$32,$B7,'Pemetaan Variant'!$O$5:$O$32),"n/a") -> 11000 | N7: =IFERROR(IF(ISNUMBER(M7),(M7-AVERAGEIF('Pemetaan Variant'!$A$5:$A$32,$B7,'Pemetaan Variant'!$D$5:$D$32))/AVERAGEIF('Pemetaan Variant'!$A$5:$A$32,$B7,'Pemetaan Variant'!$D$5:$D$32)*100,"n/a"),"n/a") -> 0 | O7: =IFERROR(IF(ISNUMBER(N7),$C7*N7,"n/a"),"n/a") -> 0 | P7: =IFERROR(AVERAGEIF('Pemetaan Variant'!$A$5:$A$32,$B7,'Pemetaan Variant'!$P$5:$P$32),"n/a") -> 11000 | Q7: =IFERROR(IF(ISNUMBER(P7),(P7-AVERAGEIF('Pemetaan Variant'!$A$5:$A$32,$B7,'Pemetaan Variant'!$D$5:$D$32))/AVERAGEIF('Pemetaan Variant'!$A$5:$A$32,$B7,'Pemetaan Variant'!$D$5:$D$32)*100,"n/a"),"n/a") -> 0 | R7: =IFERROR(IF(ISNUMBER(Q7),$C7*Q7,"n/a"),"n/a") -> 0 | S7: =IFERROR(AVERAGEIF('Pemetaan Variant'!$A$5:$A$32,$B7,'Pemetaan Variant'!$Q$5:$Q$32),"n/a") -> 11000 | T7: =IFERROR(IF(ISNUMBER(S7),(S7-AVERAGEIF('Pemetaan Variant'!$A$5:$A$32,$B7,'Pemetaan Variant'!$E$5:$E$32))/AVERAGEIF('Pemetaan Variant'!$A$5:$A$32,$B7,'Pemetaan Variant'!$E$5:$E$32)*100,"n/a"),"n/a") -> 0 | U7: =IFERROR(IF(ISNUMBER(T7),$C7*T7,"n/a"),"n/a") -> 0 | V7: =IFERROR(AVERAGEIF('Pemetaan Variant'!$A$5:$A$32,$B7,'Pemetaan Variant'!$R$5:$R$32),"n/a") -> 11000 | W7: =IFERROR(IF(ISNUMBER(V7),(V7-AVERAGEIF('Pemetaan Variant'!$A$5:$A$32,$B7,'Pemetaan Variant'!$E$5:$E$32))/AVERAGEIF('Pemetaan Variant'!$A$5:$A$32,$B7,'Pemetaan Variant'!$E$5:$E$32)*100,"n/a"),"n/a") -> 0 | X7: =IFERROR(IF(ISNUMBER(W7),$C7*W7,"n/a"),"n/a") -> 0 | Y7: =IFERROR(AVERAGEIF('Pemetaan Variant'!$A$5:$A$32,$B7,'Pemetaan Variant'!$S$5:$S$32),"n/a") -> 11000 | Z7: =IFERROR(IF(ISNUMBER(Y7),(Y7-AVERAGEIF('Pemetaan Variant'!$A$5:$A$32,$B7,'Pemetaan Variant'!$E$5:$E$32))/AVERAGEIF('Pemetaan Variant'!$A$5:$A$32,$B7,'Pemetaan Variant'!$E$5:$E$32)*100,"n/a"),"n/a") -> 0 | AA7: =IFERROR(IF(ISNUMBER(Z7),$C7*Z7,"n/a"),"n/a") -> 0 | AB7: =IFERROR(AVERAGEIF('Pemetaan Variant'!$A$5:$A$32,$B7,'Pemetaan Variant'!$T$5:$T$32),"n/a") -> 11000 | AC7: =IFERROR(IF(ISNUMBER(AB7),(AB7-AVERAGEIF('Pemetaan Variant'!$A$5:$A$32,$B7,'Pemetaan Variant'!$E$5:$E$32))/AVERAGEIF('Pemetaan Variant'!$A$5:$A$32,$B7,'Pemetaan Variant'!$E$5:$E$32)*100,"n/a"),"n/a") -> 0 | AD7: =IFERROR(IF(ISNUMBER(AC7),$C7*AC7,"n/a"),"n/a") -> 0 | AE7: =IFERROR(AVERAGEIF('Pemetaan Variant'!$A$5:$A$32,$B7,'Pemetaan Variant'!$U$5:$U$32),"n/a") -> 11000 | AF7: =IFERROR(IF(ISNUMBER(AE7),(AE7-AVERAGEIF('Pemetaan Variant'!$A$5:$A$32,$B7,'Pemetaan Variant'!$F$5:$F$32))/AVERAGEIF('Pemetaan Variant'!$A$5:$A$32,$B7,'Pemetaan Variant'!$F$5:$F$32)*100,"n/a"),"n/a") -> 0 | AG7: =IFERROR(IF(ISNUMBER(AF7),$C7*AF7,"n/a"),"n/a") -> 0 | AH7: =IFERROR(AVERAGEIF('Pemetaan Variant'!$A$5:$A$32,$B7,'Pemetaan Variant'!$V$5:$V$32),"n/a") -> 11000 | AI7: =IFERROR(IF(ISNUMBER(AH7),(AH7-AVERAGEIF('Pemetaan Variant'!$A$5:$A$32,$B7,'Pemetaan Variant'!$F$5:$F$32))/AVERAGEIF('Pemetaan Variant'!$A$5:$A$32,$B7,'Pemetaan Variant'!$F$5:$F$32)*100,"n/a"),"n/a") -> 0 | AJ7: =IFERROR(IF(ISNUMBER(AI7),$C7*AI7,"n/a"),"n/a") -> 0 | AK7: =IFERROR(AVERAGEIF('Pemetaan Variant'!$A$5:$A$32,$B7,'Pemetaan Variant'!$W$5:$W$32),"n/a") -> 11000 | AL7: =IFERROR(IF(ISNUMBER(AK7),(AK7-AVERAGEIF('Pemetaan Variant'!$A$5:$A$32,$B7,'Pemetaan Variant'!$F$5:$F$32))/AVERAGEIF('Pemetaan Variant'!$A$5:$A$32,$B7,'Pemetaan Variant'!$F$5:$F$32)*100,"n/a"),"n/a") -> 0 | AM7: =IFERROR(IF(ISNUMBER(AL7),$C7*AL7,"n/a"),"n/a") -> 0 | AN7: =IFERROR(AVERAGEIF('Pemetaan Variant'!$A$5:$A$32,$B7,'Pemetaan Variant'!$X$5:$X$32),"n/a") -> 11000 | AO7: =IFERROR(IF(ISNUMBER(AN7),(AN7-AVERAGEIF('Pemetaan Variant'!$A$5:$A$32,$B7,'Pemetaan Variant'!$F$5:$F$32))/AVERAGEIF('Pemetaan Variant'!$A$5:$A$32,$B7,'Pemetaan Variant'!$F$5:$F$32)*100,"n/a"),"n/a") -> 0 | AP7: =IFERROR(IF(ISNUMBER(AO7),$C7*AO7,"n/a"),"n/a") -> 0 | AQ7: =IFERROR(AVERAGEIF('Pemetaan Variant'!$A$5:$A$32,$B7,'Pemetaan Variant'!$Y$5:$Y$32),"n/a") -> 11000 | AR7: =IFERROR(IF(ISNUMBER(AQ7),(AQ7-AVERAGEIF('Pemetaan Variant'!$A$5:$A$32,$B7,'Pemetaan Variant'!$F$5:$F$32))/AVERAGEIF('Pemetaan Variant'!$A$5:$A$32,$B7,'Pemetaan Variant'!$F$5:$F$32)*100,"n/a"),"n/a") -> 0 | AS7: =IFERROR(IF(ISNUMBER(AR7),$C7*AR7,"n/a"),"n/a") -> 0 | AT7: =IFERROR(AVERAGEIF('Pemetaan Variant'!$A$5:$A$32,$B7,'Pemetaan Variant'!$Z$5:$Z$32),"n/a") -> 11000 | AU7: =IFERROR(IF(ISNUMBER(AT7),(AT7-AVERAGEIF('Pemetaan Variant'!$A$5:$A$32,$B7,'Pemetaan Variant'!$G$5:$G$32))/AVERAGEIF('Pemetaan Variant'!$A$5:$A$32,$B7,'Pemetaan Variant'!$G$5:$G$32)*100,"n/a"),"n/a") -> 0 | AV7: =IFERROR(IF(ISNUMBER(AU7),$C7*AU7,"n/a"),"n/a") -> 0 | AW7: =IFERROR(AVERAGEIF('Pemetaan Variant'!$A$5:$A$32,$B7,'Pemetaan Variant'!$AA$5:$AA$32),"n/a") -> 11000 | AX7: =IFERROR(IF(ISNUMBER(AW7),(AW7-AVERAGEIF('Pemetaan Variant'!$A$5:$A$32,$B7,'Pemetaan Variant'!$G$5:$G$32))/AVERAGEIF('Pemetaan Variant'!$A$5:$A$32,$B7,'Pemetaan Variant'!$G$5:$G$32)*100,"n/a"),"n/a") -> 0 | AY7: =IFERROR(IF(ISNUMBER(AX7),$C7*AX7,"n/a"),"n/a") -> 0 | AZ7: =IFERROR(AVERAGEIF('Pemetaan Variant'!$A$5:$A$32,$B7,'Pemetaan Variant'!$AB$5:$AB$32),"n/a") -> 11000 | BA7: =IFERROR(IF(ISNUMBER(AZ7),(AZ7-AVERAGEIF('Pemetaan Variant'!$A$5:$A$32,$B7,'Pemetaan Variant'!$G$5:$G$32))/AVERAGEIF('Pemetaan Variant'!$A$5:$A$32,$B7,'Pemetaan Variant'!$G$5:$G$32)*100,"n/a"),"n/a") -> 0 | BB7: =IFERROR(IF(ISNUMBER(BA7),$C7*BA7,"n/a"),"n/a") -> 0 | BC7: =IFERROR(AVERAGEIF('Pemetaan Variant'!$A$5:$A$32,$B7,'Pemetaan Variant'!$AC$5:$AC$32),"n/a") -> 11000 | BD7: =IFERROR(IF(ISNUMBER(BC7),(BC7-AVERAGEIF('Pemetaan Variant'!$A$5:$A$32,$B7,'Pemetaan Variant'!$G$5:$G$32))/AVERAGEIF('Pemetaan Variant'!$A$5:$A$32,$B7,'Pemetaan Variant'!$G$5:$G$32)*100,"n/a"),"n/a") -> 0 | BE7: =IFERROR(IF(ISNUMBER(BD7),$C7*BD7,"n/a"),"n/a") -> 0 | BF7: =IFERROR(AVERAGEIF('Pemetaan Variant'!$A$5:$A$32,$B7,'Pemetaan Variant'!$AD$5:$AD$32),"n/a") -> 11000 | BG7: =IFERROR(IF(ISNUMBER(BF7),(BF7-AVERAGEIF('Pemetaan Variant'!$A$5:$A$32,$B7,'Pemetaan Variant'!$G$5:$G$32))/AVERAGEIF('Pemetaan Variant'!$A$5:$A$32,$B7,'Pemetaan Variant'!$G$5:$G$32)*100,"n/a"),"n/a") -> 0 | BH7: =IFERROR(IF(ISNUMBER(BG7),$C7*BG7,"n/a"),"n/a") -> 0 | BI7: =IFERROR(AVERAGEIF('Pemetaan Variant'!$A$5:$A$32,$B7,'Pemetaan Variant'!$AE$5:$AE$32),"n/a") -> n/a | BJ7: =IFERROR(IF(ISNUMBER(BI7),(BI7-AVERAGEIF('Pemetaan Variant'!$A$5:$A$32,$B7,'Pemetaan Variant'!$H$5:$H$32))/AVERAGEIF('Pemetaan Variant'!$A$5:$A$32,$B7,'Pemetaan Variant'!$H$5:$H$32)*100,"n/a"),"n/a") -> n/a | BK7: =IFERROR(IF(ISNUMBER(BJ7),$C7*BJ7,"n/a"),"n/a") -> n/a | BL7: =IFERROR(AVERAGEIF('Pemetaan Variant'!$A$5:$A$32,$B7,'Pemetaan Variant'!$AF$5:$AF$32),"n/a") -> 11000 | BM7: =IFERROR(IF(ISNUMBER(BL7),(BL7-AVERAGEIF('Pemetaan Variant'!$A$5:$A$32,$B7,'Pemetaan Variant'!$H$5:$H$32))/AVERAGEIF('Pemetaan Variant'!$A$5:$A$32,$B7,'Pemetaan Variant'!$H$5:$H$32)*100,"n/a"),"n/a") -> 0 | BN7: =IFERROR(IF(ISNUMBER(BM7),$C7*BM7,"n/a"),"n/a") -> 0 | BO7: =IFERROR(AVERAGEIF('Pemetaan Variant'!$A$5:$A$32,$B7,'Pemetaan Variant'!$AG$5:$AG$32),"n/a") -> 11000 | BP7: =IFERROR(IF(ISNUMBER(BO7),(BO7-AVERAGEIF('Pemetaan Variant'!$A$5:$A$32,$B7,'Pemetaan Variant'!$H$5:$H$32))/AVERAGEIF('Pemetaan Variant'!$A$5:$A$32,$B7,'Pemetaan Variant'!$H$5:$H$32)*100,"n/a"),"n/a") -> 0 | BQ7: =IFERROR(IF(ISNUMBER(BP7),$C7*BP7,"n/a"),"n/a") -> 0 | BR7: =IFERROR(AVERAGEIF('Pemetaan Variant'!$A$5:$A$32,$B7,'Pemetaan Variant'!$AH$5:$AH$32),"n/a") -> 11000 | BS7: =IFERROR(IF(ISNUMBER(BR7),(BR7-AVERAGEIF('Pemetaan Variant'!$A$5:$A$32,$B7,'Pemetaan Variant'!$H$5:$H$32))/AVERAGEIF('Pemetaan Variant'!$A$5:$A$32,$B7,'Pemetaan Variant'!$H$5:$H$32)*100,"n/a"),"n/a") -> 0 | BT7: =IFERROR(IF(ISNUMBER(BS7),$C7*BS7,"n/a"),"n/a") -> 0 | BU7: =IFERROR(AVERAGEIF('Pemetaan Variant'!$A$5:$A$32,$B7,'Pemetaan Variant'!$AI$5:$AI$32),"n/a") -> 11000 | BV7: =IFERROR(IF(ISNUMBER(BU7),(BU7-AVERAGEIF('Pemetaan Variant'!$A$5:$A$32,$B7,'Pemetaan Variant'!$H$5:$H$32))/AVERAGEIF('Pemetaan Variant'!$A$5:$A$32,$B7,'Pemetaan Variant'!$H$5:$H$32)*100,"n/a"),"n/a") -> 0 | BW7: =IFERROR(IF(ISNUMBER(BV7),$C7*BV7,"n/a"),"n/a") -> 0 | BX7: =IFERROR(AVERAGEIF('Pemetaan Variant'!$A$5:$A$32,$B7,'Pemetaan Variant'!$AJ$5:$AJ$32),"n/a") -> 11000 | BY7: =IFERROR(IF(ISNUMBER(BX7),(BX7-AVERAGEIF('Pemetaan Variant'!$A$5:$A$32,$B7,'Pemetaan Variant'!$I$5:$I$32))/AVERAGEIF('Pemetaan Variant'!$A$5:$A$32,$B7,'Pemetaan Variant'!$I$5:$I$32)*100,"n/a"),"n/a") -> 0 | BZ7: =IFERROR(IF(ISNUMBER(BY7),$C7*BY7,"n/a"),"n/a") -> 0 | CA7: =IFERROR(AVERAGEIF('Pemetaan Variant'!$A$5:$A$32,$B7,'Pemetaan Variant'!$AK$5:$AK$32),"n/a") -> 11000 | CB7: =IFERROR(IF(ISNUMBER(CA7),(CA7-AVERAGEIF('Pemetaan Variant'!$A$5:$A$32,$B7,'Pemetaan Variant'!$I$5:$I$32))/AVERAGEIF('Pemetaan Variant'!$A$5:$A$32,$B7,'Pemetaan Variant'!$I$5:$I$32)*100,"n/a"),"n/a") -> 0 | CC7: =IFERROR(IF(ISNUMBER(CB7),$C7*CB7,"n/a"),"n/a") -> 0 | CD7: =IFERROR(AVERAGEIF('Pemetaan Variant'!$A$5:$A$32,$B7,'Pemetaan Variant'!$AL$5:$AL$32),"n/a") -> 11000 | CE7: =IFERROR(IF(ISNUMBER(CD7),(CD7-AVERAGEIF('Pemetaan Variant'!$A$5:$A$32,$B7,'Pemetaan Variant'!$I$5:$I$32))/AVERAGEIF('Pemetaan Variant'!$A$5:$A$32,$B7,'Pemetaan Variant'!$I$5:$I$32)*100,"n/a"),"n/a") -> 0 | CF7: =IFERROR(IF(ISNUMBER(CE7),$C7*CE7,"n/a"),"n/a") -> 0 | CG7: =IFERROR(AVERAGEIF('Pemetaan Variant'!$A$5:$A$32,$B7,'Pemetaan Variant'!$AM$5:$AM$32),"n/a") -> 11000 | CH7: =IFERROR(IF(ISNUMBER(CG7),(CG7-AVERAGEIF('Pemetaan Variant'!$A$5:$A$32,$B7,'Pemetaan Variant'!$I$5:$I$32))/AVERAGEIF('Pemetaan Variant'!$A$5:$A$32,$B7,'Pemetaan Variant'!$I$5:$I$32)*100,"n/a"),"n/a") -> 0 | CI7: =IFERROR(IF(ISNUMBER(CH7),$C7*CH7,"n/a"),"n/a") -> 0 | CJ7: =IFERROR(AVERAGEIF('Pemetaan Variant'!$A$5:$A$32,$B7,'Pemetaan Variant'!$AN$5:$AN$32),"n/a") -> 11000 | CK7: =IFERROR(IF(ISNUMBER(CJ7),(CJ7-AVERAGEIF('Pemetaan Variant'!$A$5:$A$32,$B7,'Pemetaan Variant'!$I$5:$I$32))/AVERAGEIF('Pemetaan Variant'!$A$5:$A$32,$B7,'Pemetaan Variant'!$I$5:$I$32)*100,"n/a"),"n/a") -> 0 | CL7: =IFERROR(IF(ISNUMBER(CK7),$C7*CK7,"n/a"),"n/a") -> 0 | CM7: =IFERROR(AVERAGEIF('Pemetaan Variant'!$A$5:$A$32,$B7,'Pemetaan Variant'!$AO$5:$AO$32),"n/a") -> 11000 | CN7: =IFERROR(IF(ISNUMBER(CM7),(CM7-AVERAGEIF('Pemetaan Variant'!$A$5:$A$32,$B7,'Pemetaan Variant'!$J$5:$J$32))/AVERAGEIF('Pemetaan Variant'!$A$5:$A$32,$B7,'Pemetaan Variant'!$J$5:$J$32)*100,"n/a"),"n/a") -> 0 | CO7: =IFERROR(IF(ISNUMBER(CN7),$C7*CN7,"n/a"),"n/a") -> 0 | CP7: =IFERROR(AVERAGEIF('Pemetaan Variant'!$A$5:$A$32,$B7,'Pemetaan Variant'!$AP$5:$AP$32),"n/a") -> 11000 | CQ7: =IFERROR(IF(ISNUMBER(CP7),(CP7-AVERAGEIF('Pemetaan Variant'!$A$5:$A$32,$B7,'Pemetaan Variant'!$J$5:$J$32))/AVERAGEIF('Pemetaan Variant'!$A$5:$A$32,$B7,'Pemetaan Variant'!$J$5:$J$32)*100,"n/a"),"n/a") -> 0 | CR7: =IFERROR(IF(ISNUMBER(CQ7),$C7*CQ7,"n/a"),"n/a") -> 0 | CS7: =IFERROR(AVERAGEIF('Pemetaan Variant'!$A$5:$A$32,$B7,'Pemetaan Variant'!$AQ$5:$AQ$32),"n/a") -> 11000 | CT7: =IFERROR(IF(ISNUMBER(CS7),(CS7-AVERAGEIF('Pemetaan Variant'!$A$5:$A$32,$B7,'Pemetaan Variant'!$J$5:$J$32))/AVERAGEIF('Pemetaan Variant'!$A$5:$A$32,$B7,'Pemetaan Variant'!$J$5:$J$32)*100,"n/a"),"n/a") -> 0 | CU7: =IFERROR(IF(ISNUMBER(CT7),$C7*CT7,"n/a"),"n/a") -> 0 | CV7: =IFERROR(AVERAGEIF('Pemetaan Variant'!$A$5:$A$32,$B7,'Pemetaan Variant'!$AR$5:$AR$32),"n/a") -> 11000 | CW7: =IFERROR(IF(ISNUMBER(CV7),(CV7-AVERAGEIF('Pemetaan Variant'!$A$5:$A$32,$B7,'Pemetaan Variant'!$J$5:$J$32))/AVERAGEIF('Pemetaan Variant'!$A$5:$A$32,$B7,'Pemetaan Variant'!$J$5:$J$32)*100,"n/a"),"n/a") -> 0 | CX7: =IFERROR(IF(ISNUMBER(CW7),$C7*CW7,"n/a"),"n/a") -> 0 | CY7: =IFERROR(AVERAGEIF('Pemetaan Variant'!$A$5:$A$32,$B7,'Pemetaan Variant'!$AS$5:$AS$32),"n/a") -> 11000 | CZ7: =IFERROR(IF(ISNUMBER(CY7),(CY7-AVERAGEIF('Pemetaan Variant'!$A$5:$A$32,$B7,'Pemetaan Variant'!$J$5:$J$32))/AVERAGEIF('Pemetaan Variant'!$A$5:$A$32,$B7,'Pemetaan Variant'!$J$5:$J$32)*100,"n/a"),"n/a") -> 0 | DA7: =IFERROR(IF(ISNUMBER(CZ7),$C7*CZ7,"n/a"),"n/a") -> 0 | DB7: =IFERROR(AVERAGEIF('Pemetaan Variant'!$A$5:$A$32,$B7,'Pemetaan Variant'!$AT$5:$AT$32),"n/a") -> 11000 | DC7: =IFERROR(IF(ISNUMBER(DB7),(DB7-AVERAGEIF('Pemetaan Variant'!$A$5:$A$32,$B7,'Pemetaan Variant'!$K$5:$K$32))/AVERAGEIF('Pemetaan Variant'!$A$5:$A$32,$B7,'Pemetaan Variant'!$K$5:$K$32)*100,"n/a"),"n/a") -> 0 | DD7: =IFERROR(IF(ISNUMBER(DC7),$C7*DC7,"n/a"),"n/a") -> 0 | DE7: =IFERROR(AVERAGEIF('Pemetaan Variant'!$A$5:$A$32,$B7,'Pemetaan Variant'!$AU$5:$AU$32),"n/a") -> 11000 | DF7: =IFERROR(IF(ISNUMBER(DE7),(DE7-AVERAGEIF('Pemetaan Variant'!$A$5:$A$32,$B7,'Pemetaan Variant'!$K$5:$K$32))/AVERAGEIF('Pemetaan Variant'!$A$5:$A$32,$B7,'Pemetaan Variant'!$K$5:$K$32)*100,"n/a"),"n/a") -> 0 | DG7: =IFERROR(IF(ISNUMBER(DF7),$C7*DF7,"n/a"),"n/a") -> 0 | DH7: =IFERROR(AVERAGEIF('Pemetaan Variant'!$A$5:$A$32,$B7,'Pemetaan Variant'!$AV$5:$AV$32),"n/a") -> 11000 | DI7: =IFERROR(IF(ISNUMBER(DH7),(DH7-AVERAGEIF('Pemetaan Variant'!$A$5:$A$32,$B7,'Pemetaan Variant'!$K$5:$K$32))/AVERAGEIF('Pemetaan Variant'!$A$5:$A$32,$B7,'Pemetaan Variant'!$K$5:$K$32)*100,"n/a"),"n/a") -> 0 | DJ7: =IFERROR(IF(ISNUMBER(DI7),$C7*DI7,"n/a"),"n/a") -> 0 | DK7: =IFERROR(AVERAGEIF('Pemetaan Variant'!$A$5:$A$32,$B7,'Pemetaan Variant'!$AW$5:$AW$32),"n/a") -> 11000 | DL7: =IFERROR(IF(ISNUMBER(DK7),(DK7-AVERAGEIF('Pemetaan Variant'!$A$5:$A$32,$B7,'Pemetaan Variant'!$K$5:$K$32))/AVERAGEIF('Pemetaan Variant'!$A$5:$A$32,$B7,'Pemetaan Variant'!$K$5:$K$32)*100,"n/a"),"n/a") -> 0 | DM7: =IFERROR(IF(ISNUMBER(DL7),$C7*DL7,"n/a"),"n/a") -> 0 | DN7: =IFERROR(AVERAGEIF('Pemetaan Variant'!$A$5:$A$32,$B7,'Pemetaan Variant'!$AZ$5:$AZ$32),"n/a") -> 11000 | DO7: =IFERROR(IF(ISNUMBER(DN7),(DN7-AVERAGEIF('Pemetaan Variant'!$A$5:$A$32,$B7,'Pemetaan Variant'!$AY$5:$AY$32))/AVERAGEIF('Pemetaan Variant'!$A$5:$A$32,$B7,'Pemetaan Variant'!$AY$5:$AY$32)*100,"n/a"),"n/a") -> 0 | DP7: =IFERROR(IF(ISNUMBER(DO7),$C7*DO7,"n/a"),"n/a") -> 0 | DQ7: =IFERROR(AVERAGEIF('Pemetaan Variant'!$A$5:$A$32,$B7,'Pemetaan Variant'!$BA$5:$BA$32),"n/a") -> n/a | DR7: =IFERROR(IF(ISNUMBER(DQ7),(DQ7-AVERAGEIF('Pemetaan Variant'!$A$5:$A$32,$B7,'Pemetaan Variant'!$AY$5:$AY$32))/AVERAGEIF('Pemetaan Variant'!$A$5:$A$32,$B7,'Pemetaan Variant'!$AY$5:$AY$32)*100,"n/a"),"n/a") -> n/a | DS7: =IFERROR(IF(ISNUMBER(DR7),$C7*DR7,"n/a"),"n/a") -> n/a | DT7: =IFERROR(AVERAGEIF('Pemetaan Variant'!$A$5:$A$32,$B7,'Pemetaan Variant'!$BB$5:$BB$32),"n/a") -> n/a | DU7: =IFERROR(IF(ISNUMBER(DT7),(DT7-AVERAGEIF('Pemetaan Variant'!$A$5:$A$32,$B7,'Pemetaan Variant'!$AY$5:$AY$32))/AVERAGEIF('Pemetaan Variant'!$A$5:$A$32,$B7,'Pemetaan Variant'!$AY$5:$AY$32)*100,"n/a"),"n/a") -> n/a | DV7: =IFERROR(IF(ISNUMBER(DU7),$C7*DU7,"n/a"),"n/a") -> n/a | DW7: =IFERROR(AVERAGEIF('Pemetaan Variant'!$A$5:$A$32,$B7,'Pemetaan Variant'!$BC$5:$BC$32),"n/a") -> n/a | DX7: =IFERROR(IF(ISNUMBER(DW7),(DW7-AVERAGEIF('Pemetaan Variant'!$A$5:$A$32,$B7,'Pemetaan Variant'!$AY$5:$AY$32))/AVERAGEIF('Pemetaan Variant'!$A$5:$A$32,$B7,'Pemetaan Variant'!$AY$5:$AY$32)*100,"n/a"),"n/a") -> n/a | DY7: =IFERROR(IF(ISNUMBER(DX7),$C7*DX7,"n/a"),"n/a") -> n/a | DZ7: =IFERROR(AVERAGEIF('Pemetaan Variant'!$A$5:$A$32,$B7,'Pemetaan Variant'!$BD$5:$BD$32),"n/a") -> n/a | EA7: =IFERROR(IF(ISNUMBER(DZ7),(DZ7-AVERAGEIF('Pemetaan Variant'!$A$5:$A$32,$B7,'Pemetaan Variant'!$AY$5:$AY$32))/AVERAGEIF('Pemetaan Variant'!$A$5:$A$32,$B7,'Pemetaan Variant'!$AY$5:$AY$32)*100,"n/a"),"n/a") -> n/a | EB7: =IFERROR(IF(ISNUMBER(EA7),$C7*EA7,"n/a"),"n/a") -> n/a | ED7: =IFERROR(ABS(F7),0) -> 0 | EE7: =IFERROR(ABS(I7),0) -> 0 | EF7: =IFERROR(ABS(L7),0) -> 0 | EG7: =IFERROR(ABS(O7),0) -> 0 | EH7: =IFERROR(ABS(R7),0) -> 0 | EI7: =IFERROR(ABS(U7),0) -> 0 | EJ7: =IFERROR(ABS(X7),0) -> 0 | EK7: =IFERROR(ABS(AA7),0) -> 0 | EL7: =IFERROR(ABS(AD7),0) -> 0 | EM7: =IFERROR(ABS(AG7),0) -> 0 | EN7: =IFERROR(ABS(AJ7),0) -> 0 | EO7: =IFERROR(ABS(AM7),0) -> 0 | EP7: =IFERROR(ABS(AP7),0) -> 0 | EQ7: =IFERROR(ABS(AS7),0) -> 0 | ER7: =IFERROR(ABS(AV7),0) -> 0 | ES7: =IFERROR(ABS(AY7),0) -> 0 | ET7: =IFERROR(ABS(BB7),0) -> 0 | EU7: =IFERROR(ABS(BE7),0) -> 0 | EV7: =IFERROR(ABS(BH7),0) -> 0 | EW7: =IFERROR(ABS(BK7),0) -> 0 | EX7: =IFERROR(ABS(BN7),0) -> 0 | EY7: =IFERROR(ABS(BQ7),0) -> 0 | EZ7: =IFERROR(ABS(BT7),0) -> 0 | FA7: =IFERROR(ABS(BW7),0) -> 0 | FB7: =IFERROR(ABS(BZ7),0) -> 0 | FC7: =IFERROR(ABS(CC7),0) -> 0 | FD7: =IFERROR(ABS(CF7),0) -> 0 | FE7: =IFERROR(ABS(CI7),0) -> 0 | FF7: =IFERROR(ABS(CL7),0) -> 0 | FG7: =IFERROR(ABS(CO7),0) -> 0 | FH7: =IFERROR(ABS(CR7),0) -> 0 | FI7: =IFERROR(ABS(CU7),0) -> 0 | FJ7: =IFERROR(ABS(CX7),0) -> 0 | FK7: =IFERROR(ABS(DA7),0) -> 0 | FL7: =IFERROR(ABS(DD7),0) -> 0 | FM7: =IFERROR(ABS(DG7),0) -> 0 | FN7: =IFERROR(ABS(DJ7),0) -> 0 | FO7: =IFERROR(ABS(DM7),0) -> 0 | FP7: =IFERROR(ABS(#REF!),0) -> 0 | FQ7: =IFERROR(ABS(DP7),0) -> 0 | FR7: =IFERROR(ABS(DS7),0) -> 0 | FS7: =IFERROR(ABS(DV7),0) -> 0 | FT7: =IFERROR(ABS(DY7),0) -> 0 | FU7: =IFERROR(ABS(EB7),0) -> 0
