Workbook

Sheet Ringkasan Mingguan 2026
A1: RINGKASAN GROWTH IPH MINGGUAN JANUARI - DESEMBER 2026 (Pasar Pon Jombang)
A3: No | B3: Bulan - Minggu | C3: Rentang Tanggal | D3: Growth IPH (%) | E3: Arah
A4: 1 | B4: Jan 2026 - M1 | C4: 2026-01-01 s/d 2026-01-03 | D4: ='Perhitungan IPH Mingguan 2026'!F26 -> 1.153014 | E4: =IF(ISNUMBER(D4),IF(D4>0,"Naik","Turun"),"-") -> Naik
A5: 2 | B5: Jan 2026 - M2 | C5: 2026-01-06 s/d 2026-01-10 | D5: ='Perhitungan IPH Mingguan 2026'!I26 -> 0.15142597 | E5: =IF(ISNUMBER(D5),IF(D5>0,"Naik","Turun"),"-") -> Naik
A6: 3 | B6: Jan 2026 - M3 | C6: 2026-01-13 s/d 2026-01-17 | D6: ='Perhitungan IPH Mingguan 2026'!L26 -> -0.25084793 | E6: =IF(ISNUMBER(D6),IF(D6>0,"Naik","Turun"),"-") -> Turun
A7: 4 | B7: Jan 2026 - M4 | C7: 2026-01-20 s/d 2026-01-24 | D7: ='Perhitungan IPH Mingguan 2026'!O26 -> -0.30159399 | E7: =IF(ISNUMBER(D7),IF(D7>0,"Naik","Turun"),"-") -> Turun
A8: 5 | B8: Jan 2026 - M5 | C8: 2026-01-27 s/d 2026-01-31 | D8: ='Perhitungan IPH Mingguan 2026'!R26 -> -0.10571837 | E8: =IF(ISNUMBER(D8),IF(D8>0,"Naik","Turun"),"-") -> Turun
A9: 6 | B9: Feb 2026 - M1 | C9: 2026-02-03 s/d 2026-02-07 | D9: ='Perhitungan IPH Mingguan 2026'!U26 -> -0.11346943 | E9: =IF(ISNUMBER(D9),IF(D9>0,"Naik","Turun"),"-") -> Turun
A10: 7 | B10: Feb 2026 - M2 | C10: 2026-02-10 s/d 2026-02-14 | D10: ='Perhitungan IPH Mingguan 2026'!X26 -> 0.25352495 | E10: =IF(ISNUMBER(D10),IF(D10>0,"Naik","Turun"),"-") -> Naik
A11: 8 | B11: Feb 2026 - M3 | C11: 2026-02-17 s/d 2026-02-21 | D11: ='Perhitungan IPH Mingguan 2026'!AA26 -> 0.56512699 | E11: =IF(ISNUMBER(D11),IF(D11>0,"Naik","Turun"),"-") -> Naik
A12: 9 | B12: Feb 2026 - M4 | C12: 2026-02-24 s/d 2026-02-28 | D12: ='Perhitungan IPH Mingguan 2026'!AD26 -> 0.66673852 | E12: =IF(ISNUMBER(D12),IF(D12>0,"Naik","Turun"),"-") -> Naik
A13: 10 | B13: Mar 2026 - M1 | C13: 2026-03-03 s/d 2026-03-07 | D13: ='Perhitungan IPH Mingguan 2026'!AG26 -> -0.19664309 | E13: =IF(ISNUMBER(D13),IF(D13>0,"Naik","Turun"),"-") -> Turun
A14: 11 | B14: Mar 2026 - M2 | C14: 2026-03-10 s/d 2026-03-14 | D14: ='Perhitungan IPH Mingguan 2026'!AJ26 -> -0.49580176 | E14: =IF(ISNUMBER(D14),IF(D14>0,"Naik","Turun"),"-") -> Turun
A15: 12 | B15: Mar 2026 - M3 | C15: 2026-03-17 s/d 2026-03-21 | D15: ='Perhitungan IPH Mingguan 2026'!AM26 -> -0.38663971 | E15: =IF(ISNUMBER(D15),IF(D15>0,"Naik","Turun"),"-") -> Turun
A16: 13 | B16: Mar 2026 - M4 | C16: 2026-03-24 s/d 2026-03-28 | D16: ='Perhitungan IPH Mingguan 2026'!AP26 -> -0.18705727 | E16: =IF(ISNUMBER(D16),IF(D16>0,"Naik","Turun"),"-") -> Turun
A17: 14 | B17: Mar 2026 - M5 | C17: 2026-03-31 s/d 2026-03-31 | D17: ='Perhitungan IPH Mingguan 2026'!AS26 -> Data tidak tersedia | E17: =IF(ISNUMBER(D17),IF(D17>0,"Naik","Turun"),"-") -> -
A18: 15 | B18: Apr 2026 - M1 | C18: 2026-04-01 s/d 2026-04-04 | D18: ='Perhitungan IPH Mingguan 2026'!AV26 -> Data tidak tersedia | E18: =IF(ISNUMBER(D18),IF(D18>0,"Naik","Turun"),"-") -> -
A19: 16 | B19: Apr 2026 - M2 | C19: 2026-04-07 s/d 2026-04-11 | D19: ='Perhitungan IPH Mingguan 2026'!AY26 -> 1.3979464 | E19: =IF(ISNUMBER(D19),IF(D19>0,"Naik","Turun"),"-") -> Naik
A20: 17 | B20: Apr 2026 - M3 | C20: 2026-04-14 s/d 2026-04-18 | D20: ='Perhitungan IPH Mingguan 2026'!BB26 -> 0.15108691 | E20: =IF(ISNUMBER(D20),IF(D20>0,"Naik","Turun"),"-") -> Naik
A21: 18 | B21: Apr 2026 - M4 | C21: 2026-04-21 s/d 2026-04-25 | D21: ='Perhitungan IPH Mingguan 2026'!BE26 -> -0.73894569 | E21: =IF(ISNUMBER(D21),IF(D21>0,"Naik","Turun"),"-") -> Turun
A22: 19 | B22: Apr 2026 - M5 | C22: 2026-04-28 s/d 2026-04-30 | D22: ='Perhitungan IPH Mingguan 2026'!BH26 -> -2.9422084 | E22: =IF(ISNUMBER(D22),IF(D22>0,"Naik","Turun"),"-") -> Turun
A23: 20 | B23: Mei 2026 - M1 | C23: 2026-05-01 s/d 2026-05-02 | D23: ='Perhitungan IPH Mingguan 2026'!BK26 -> -2.7846873 | E23: =IF(ISNUMBER(D23),IF(D23>0,"Naik","Turun"),"-") -> Turun
A24: 21 | B24: Mei 2026 - M2 | C24: 2026-05-05 s/d 2026-05-09 | D24: ='Perhitungan IPH Mingguan 2026'!BN26 -> -2.619292 | E24: =IF(ISNUMBER(D24),IF(D24>0,"Naik","Turun"),"-") -> Turun
A25: 22 | B25: Mei 2026 - M3 | C25: 2026-05-12 s/d 2026-05-16 | D25: ='Perhitungan IPH Mingguan 2026'!BQ26 -> -2.6757648 | E25: =IF(ISNUMBER(D25),IF(D25>0,"Naik","Turun"),"-") -> Turun
A26: 23 | B26: Mei 2026 - M4 | C26: 2026-05-19 s/d 2026-05-23 | D26: ='Perhitungan IPH Mingguan 2026'!BT26 -> -2.6305095 | E26: =IF(ISNUMBER(D26),IF(D26>0,"Naik","Turun"),"-") -> Turun
A27: 24 | B27: Mei 2026 - M5 | C27: 2026-05-26 s/d 2026-05-30 | D27: ='Perhitungan IPH Mingguan 2026'!BW26 -> -2.1536788 | E27: =IF(ISNUMBER(D27),IF(D27>0,"Naik","Turun"),"-") -> Turun
A28: 25 | B28: Jun 2026 - M1 | C28: 2026-06-02 s/d 2026-06-06 | D28: ='Perhitungan IPH Mingguan 2026'!BZ26 -> 2.1033152 | E28: =IF(ISNUMBER(D28),IF(D28>0,"Naik","Turun"),"-") -> Naik
A29: 26 | B29: Jun 2026 - M2 | C29: 2026-06-09 s/d 2026-06-13 | D29: ='Perhitungan IPH Mingguan 2026'!CC26 -> -0.06680902 | E29: =IF(ISNUMBER(D29),IF(D29>0,"Naik","Turun"),"-") -> Turun
A30: 27 | B30: Jun 2026 - M3 | C30: 2026-06-16 s/d 2026-06-20 | D30: ='Perhitungan IPH Mingguan 2026'!CF26 -> -2.6092598 | E30: =IF(ISNUMBER(D30),IF(D30>0,"Naik","Turun"),"-") -> Turun
A31: 28 | B31: Jun 2026 - M4 | C31: 2026-06-23 s/d 2026-06-27 | D31: ='Perhitungan IPH Mingguan 2026'!CI26 -> -2.1984712 | E31: =IF(ISNUMBER(D31),IF(D31>0,"Naik","Turun"),"-") -> Turun
A32: 29 | B32: Jul 2026 - M1 | C32: 2026-07-01 s/d 2026-07-04 | D32: ='Perhitungan IPH Mingguan 2026'!CL26 -> -0.41679672 | E32: =IF(ISNUMBER(D32),IF(D32>0,"Naik","Turun"),"-") -> Turun
A33: 30 | B33: Jul 2026 - M2 | C33: 2026-07-07 s/d 2026-07-11 | D33: ='Perhitungan IPH Mingguan 2026'!CO26 -> 1.4606367 | E33: =IF(ISNUMBER(D33),IF(D33>0,"Naik","Turun"),"-") -> Naik
A34: 31 | B34: Jul 2026 - M3 | C34: 2026-07-14 s/d 2026-07-18 | D34: ='Perhitungan IPH Mingguan 2026'!CR26 -> 1.0420114 | E34: =IF(ISNUMBER(D34),IF(D34>0,"Naik","Turun"),"-") -> Naik
A35: 32 | B35: Jul 2026 - M4 | C35: 2026-07-21 s/d 2026-07-25 | D35: ='Perhitungan IPH Mingguan 2026'!CU26 -> 2.1075933 | E35: =IF(ISNUMBER(D35),IF(D35>0,"Naik","Turun"),"-") -> Naik
A36: 33 | B36: Jul 2026 - M5 | C36: 2026-07-28 s/d 2026-07-31 | D36: ='Perhitungan IPH Mingguan 2026'!CX26 -> 1.6725606 | E36: =IF(ISNUMBER(D36),IF(D36>0,"Naik","Turun"),"-") -> Naik

Sheet Perhitungan IPH Mingguan 2026
A1: PERHITUNGAN IPH MINGGUAN JANUARI - DESEMBER 2025 (55 minggu) - PASAR PON JOMBANG
A2: Formula: Andil_i(Mt) = Bobot_i x [(P̄Mt,i - P̄bulan sebelumnya,i)/P̄bulan sebelumnya,i] x 100% ; Growth IPH(Mt) = Σ Andil_i(Mt). Acuan m-1 tiap minggu = rata-rata bulan kalender sebelumnya (mis. minggu2 Januari acuan = rata2 Desember 2024).
D4: Jan 2025 - M1 (01-03) | G4: Jan 2025 - M2 (06-10) | J4: Jan 2025 - M3 (13-17) | M4: Jan 2025 - M4 (20-24) | P4: Jan 2025 - M5 (27-31) | S4: Feb 2025 - M1 (03-07) | V4: Feb 2025 - M2 (10-14) | Y4: Feb 2025 - M3 (17-21) | AB4: Feb 2025 - M4 (24-28) | AE4: Mar 2025 - M1 (03-07) | AH4: Mar 2025 - M2 (10-14) | AK4: Mar 2025 - M3 (17-21) | AN4: Mar 2025 - M4 (24-28) | AQ4: Mar 2025 - M5 (31-31) | AT4: Apr 2025 - M1 (01-04) | AW4: Apr 2025 - M2 (07-11) | AZ4: Apr 2025 - M3 (14-18) | BC4: Apr 2025 - M4 (21-25) | BF4: Apr 2025 - M5 (28-30) | BI4: Mei 2025 - M1 (01-02) | BL4: Mei 2025 - M2 (05-09) | BO4: Mei 2025 - M3 (12-16) | BR4: Mei 2025 - M4 (19-23) | BU4: Mei 2025 - M5 (26-30) | BX4: Jun 2025 - M1 (02-06) | CA4: Jun 2025 - M2 (09-13) | CD4: Jun 2025 - M3 (16-20) | CG4: Jun 2025 - M4 (23-27) | CJ4: Jul 2025 - M1 (01-04) | CM4: Jul 2025 - M2 (07-11) | CP4: Jul 2025 - M3 (14-18) | CS4: Jul 2025 - M4 (21-25) | CV4: Jul 2025 - M5 (28-31) | CY4: Agu 2025 - M1 (04-08) | DB4: Agu 2025 - M2 (11-15) | DE4: Agu 2025 - M3 (18-22) | DH4: Agu 2025 - M4 (25-29) | DK4: Sep 2025 - M1 (01-05) | DN4: Sep 2025 - M2 (08-12) | DQ4: Sep 2025 - M3 (15-19) | DT4: Sep 2025 - M4 (22-26) | DW4: Okt 2025 - M1 (01-03) | DZ4: Okt 2025 - M2 (06-10) | EC4: Okt 2025 - M3 (13-17) | EF4: Okt 2025 - M4 (20-24) | EI4: Okt 2025 - M5 (27-31) | EL4: Nov 2025 - M1 (03-07) | EO4: Nov 2025 - M2 (10-14) | ER4: Nov 2025 - M3 (17-21) | EU4: Nov 2025 - M4 (24-28) | EX4: Des 2025 - M1 (01-05) | FA4: Des 2025 - M2 (08-12) | FD4: Des 2025 - M3 (15-19) | FG4: Des 2025 - M4 (22-26) | FJ4: Des 2025 - M5 (29-31)
A5: No | B5: Komoditas (standar IPH) | C5: Bobot (wi) | D5: P̄ | E5: Growth% | F5: Andil% | G5: P̄ | H5: Growth% | I5: Andil% | J5: P̄ | K5: Growth% | L5: Andil% | M5: P̄ | N5: Growth% | O5: Andil% | P5: P̄ | Q5: Growth% | R5: Andil% | S5: P̄ | T5: Growth% | U5: Andil% | V5: P̄ | W5: Growth% | X5: Andil% | Y5: P̄ | Z5: Growth% | AA5: Andil% | AB5: P̄ | AC5: Growth% | AD5: Andil% | AE5: P̄ | AF5: Growth% | AG5: Andil% | AH5: P̄ | AI5: Growth% | AJ5: Andil% | AK5: P̄ | AL5: Growth% | AM5: Andil% | AN5: P̄ | AO5: Growth% | AP5: Andil% | AQ5: P̄ | AR5: Growth% | AS5: Andil% | AT5: P̄ | AU5: Growth% | AV5: Andil% | AW5: P̄ | AX5: Growth% | AY5: Andil% | AZ5: P̄ | BA5: Growth% | BB5: Andil% | BC5: P̄ | BD5: Growth% | BE5: Andil% | BF5: P̄ | BG5: Growth% | BH5: Andil% | BI5: P̄ | BJ5: Growth% | BK5: Andil% | BL5: P̄ | BM5: Growth% | BN5: Andil% | BO5: P̄ | BP5: Growth% | BQ5: Andil% | BR5: P̄ | BS5: Growth% | BT5: Andil% | BU5: P̄ | BV5: Growth% | BW5: Andil% | BX5: P̄ | BY5: Growth% | BZ5: Andil% | CA5: P̄ | CB5: Growth% | CC5: Andil% | CD5: P̄ | CE5: Growth% | CF5: Andil% | CG5: P̄ | CH5: Growth% | CI5: Andil% | CJ5: P̄ | CK5: Growth% | CL5: Andil% | CM5: P̄ | CN5: Growth% | CO5: Andil% | CP5: P̄ | CQ5: Growth% | CR5: Andil% | CS5: P̄ | CT5: Growth% | CU5: Andil% | CV5: P̄ | CW5: Growth% | CX5: Andil% | CY5: P̄ | CZ5: Growth% | DA5: Andil% | DB5: P̄ | DC5: Growth% | DD5: Andil% | DE5: P̄ | DF5: Growth% | DG5: Andil% | DH5: P̄ | DI5: Growth% | DJ5: Andil% | DK5: P̄ | DL5: Growth% | DM5: Andil% | DN5: P̄ | DO5: Growth% | DP5: Andil% | DQ5: P̄ | DR5: Growth% | DS5: Andil% | DT5: P̄ | DU5: Growth% | DV5: Andil% | DW5: P̄ | DX5: Growth% | DY5: Andil% | DZ5: P̄ | EA5: Growth% | EB5: Andil% | EC5: P̄ | ED5: Growth% | EE5: Andil% | EF5: P̄ | EG5: Growth% | EH5: Andil% | EI5: P̄ | EJ5: Growth% | EK5: Andil% | EL5: P̄ | EM5: Growth% | EN5: Andil% | EO5: P̄ | EP5: Growth% | EQ5: Andil% | ER5: P̄ | ES5: Growth% | ET5: Andil% | EU5: P̄ | EV5: Growth% | EW5: Andil% | EX5: P̄ | EY5: Growth% | EZ5: Andil% | FA5: P̄ | FB5: Growth% | FC5: Andil% | FD5: P̄ | FE5: Growth% | FF5: Andil% | FG5: P̄ | FH5: Growth% | FI5: Andil% | FJ5: P̄ | FK5: Growth% | FL5: Andil% | FM5: Catatan Pemetaan | FO5: ABS[Jan 2025-M1] | FP5: ABS[Jan 2025-M2] | FQ5: ABS[Jan 2025-M3] | FR5: ABS[Jan 2025-M4] | FS5: ABS[Jan 2025-M5] | FT5: ABS[Feb 2025-M1] | FU5: ABS[Feb 2025-M2] | FV5: ABS[Feb 2025-M3] | FW5: ABS[Feb 2025-M4] | FX5: ABS[Mar 2025-M1] | FY5: ABS[Mar 2025-M2] | FZ5: ABS[Mar 2025-M3] | GA5: ABS[Mar 2025-M4] | GB5: ABS[Mar 2025-M5] | GC5: ABS[Apr 2025-M1] | GD5: ABS[Apr 2025-M2] | GE5: ABS[Apr 2025-M3] | GF5: ABS[Apr 2025-M4] | GG5: ABS[Apr 2025-M5] | GH5: ABS[Mei 2025-M1] | GI5: ABS[Mei 2025-M2] | GJ5: ABS[Mei 2025-M3] | GK5: ABS[Mei 2025-M4] | GL5: ABS[Mei 2025-M5] | GM5: ABS[Jun 2025-M1] | GN5: ABS[Jun 2025-M2] | GO5: ABS[Jun 2025-M3] | GP5: ABS[Jun 2025-M4] | GQ5: ABS[Jul 2025-M1] | GR5: ABS[Jul 2025-M2] | GS5: ABS[Jul 2025-M3] | GT5: ABS[Jul 2025-M4] | GU5: ABS[Jul 2025-M5] | GV5: ABS[Agu 2025-M1] | GW5: ABS[Agu 2025-M2] | GX5: ABS[Agu 2025-M3] | GY5: ABS[Agu 2025-M4] | GZ5: ABS[Sep 2025-M1] | HA5: ABS[Sep 2025-M2] | HB5: ABS[Sep 2025-M3] | HC5: ABS[Sep 2025-M4] | HD5: ABS[Okt 2025-M1] | HE5: ABS[Okt 2025-M2] | HF5: ABS[Okt 2025-M3] | HG5: ABS[Okt 2025-M4] | HH5: ABS[Okt 2025-M5] | HI5: ABS[Nov 2025-M1] | HJ5: ABS[Nov 2025-M2] | HK5: ABS[Nov 2025-M3] | HL5: ABS[Nov 2025-M4] | HM5: ABS[Des 2025-M1] | HN5: ABS[Des 2025-M2] | HO5: ABS[Des 2025-M3] | HP5: ABS[Des 2025-M4] | HQ5: ABS[Des 2025-M5]
A6: 1 | B6: beras 1111001 | C6: ='P0Q0 Dasar 2022'!F5 -> 0.12508906 | D6: =IFERROR(AVERAGEIF('Pemetaan Variant'!$A$5:$A$32,$B6,'Pemetaan Variant'!$P$5:$P$32),"n/a") -> 12500 | E6: =IFERROR(IF(ISNUMBER(D6),(D6-AVERAGEIF('Pemetaan Variant'!$A$5:$A$32,$B6,'Pemetaan Variant'!$D$5:$D$32))/AVERAGEIF('Pemetaan Variant'!$A$5:$A$32,$B6,'Pemetaan Variant'!$D$5:$D$32)*100,"n/a"),"n/a") -> 0 | F6: =IFERROR(IF(ISNUMBER(E6),$C6*E6,"n/a"),"n/a") -> 0 | G6: =IFERROR(AVERAGEIF('Pemetaan Variant'!$A$5:$A$32,$B6,'Pemetaan Variant'!$Q$5:$Q$32),"n/a") -> 12500 | H6: =IFERROR(IF(ISNUMBER(G6),(G6-AVERAGEIF('Pemetaan Variant'!$A$5:$A$32,$B6,'Pemetaan Variant'!$D$5:$D$32))/AVERAGEIF('Pemetaan Variant'!$A$5:$A$32,$B6,'Pemetaan Variant'!$D$5:$D$32)*100,"n/a"),"n/a") -> 0 | I6: =IFERROR(IF(ISNUMBER(H6),$C6*H6,"n/a"),"n/a") -> 0 | J6: =IFERROR(AVERAGEIF('Pemetaan Variant'!$A$5:$A$32,$B6,'Pemetaan Variant'!$R$5:$R$32),"n/a") -> 12500 | K6: =IFERROR(IF(ISNUMBER(J6),(J6-AVERAGEIF('Pemetaan Variant'!$A$5:$A$32,$B6,'Pemetaan Variant'!$D$5:$D$32))/AVERAGEIF('Pemetaan Variant'!$A$5:$A$32,$B6,'Pemetaan Variant'!$D$5:$D$32)*100,"n/a"),"n/a") -> 0 | L6: =IFERROR(IF(ISNUMBER(K6),$C6*K6,"n/a"),"n/a") -> 0 | M6: =IFERROR(AVERAGEIF('Pemetaan Variant'!$A$5:$A$32,$B6,'Pemetaan Variant'!$S$5:$S$32),"n/a") -> 12500 | N6: =IFERROR(IF(ISNUMBER(M6),(M6-AVERAGEIF('Pemetaan Variant'!$A$5:$A$32,$B6,'Pemetaan Variant'!$D$5:$D$32))/AVERAGEIF('Pemetaan Variant'!$A$5:$A$32,$B6,'Pemetaan Variant'!$D$5:$D$32)*100,"n/a"),"n/a") -> 0 | O6: =IFERROR(IF(ISNUMBER(N6),$C6*N6,"n/a"),"n/a") -> 0 | P6: =IFERROR(AVERAGEIF('Pemetaan Variant'!$A$5:$A$32,$B6,'Pemetaan Variant'!$T$5:$T$32),"n/a") -> 12500 | Q6: =IFERROR(IF(ISNUMBER(P6),(P6-AVERAGEIF('Pemetaan Variant'!$A$5:$A$32,$B6,'Pemetaan Variant'!$D$5:$D$32))/AVERAGEIF('Pemetaan Variant'!$A$5:$A$32,$B6,'Pemetaan Variant'!$D$5:$D$32)*100,"n/a"),"n/a") -> 0 | R6: =IFERROR(IF(ISNUMBER(Q6),$C6*Q6,"n/a"),"n/a") -> 0 | S6: =IFERROR(AVERAGEIF('Pemetaan Variant'!$A$5:$A$32,$B6,'Pemetaan Variant'!$U$5:$U$32),"n/a") -> 12500 | T6: =IFERROR(IF(ISNUMBER(S6),(S6-AVERAGEIF('Pemetaan Variant'!$A$5:$A$32,$B6,'Pemetaan Variant'!$E$5:$E$32))/AVERAGEIF('Pemetaan Variant'!$A$5:$A$32,$B6,'Pemetaan Variant'!$E$5:$E$32)*100,"n/a"),"n/a") -> 0 | U6: =IFERROR(IF(ISNUMBER(T6),$C6*T6,"n/a"),"n/a") -> 0 | V6: =IFERROR(AVERAGEIF('Pemetaan Variant'!$A$5:$A$32,$B6,'Pemetaan Variant'!$V$5:$V$32),"n/a") -> 12500 | W6: =IFERROR(IF(ISNUMBER(V6),(V6-AVERAGEIF('Pemetaan Variant'!$A$5:$A$32,$B6,'Pemetaan Variant'!$E$5:$E$32))/AVERAGEIF('Pemetaan Variant'!$A$5:$A$32,$B6,'Pemetaan Variant'!$E$5:$E$32)*100,"n/a"),"n/a") -> 0 | X6: =IFERROR(IF(ISNUMBER(W6),$C6*W6,"n/a"),"n/a") -> 0 | Y6: =IFERROR(AVERAGEIF('Pemetaan Variant'!$A$5:$A$32,$B6,'Pemetaan Variant'!$W$5:$W$32),"n/a") -> 12500 | Z6: =IFERROR(IF(ISNUMBER(Y6),(Y6-AVERAGEIF('Pemetaan Variant'!$A$5:$A$32,$B6,'Pemetaan Variant'!$E$5:$E$32))/AVERAGEIF('Pemetaan Variant'!$A$5:$A$32,$B6,'Pemetaan Variant'!$E$5:$E$32)*100,"n/a"),"n/a") -> 0 | AA6: =IFERROR(IF(ISNUMBER(Z6),$C6*Z6,"n/a"),"n/a") -> 0 | AB6: =IFERROR(AVERAGEIF('Pemetaan Variant'!$A$5:$A$32,$B6,'Pemetaan Variant'!$X$5:$X$32),"n/a") -> 12500 | AC6: =IFERROR(IF(ISNUMBER(AB6),(AB6-AVERAGEIF('Pemetaan Variant'!$A$5:$A$32,$B6,'Pemetaan Variant'!$E$5:$E$32))/AVERAGEIF('Pemetaan Variant'!$A$5:$A$32,$B6,'Pemetaan Variant'!$E$5:$E$32)*100,"n/a"),"n/a") -> 0 | AD6: =IFERROR(IF(ISNUMBER(AC6),$C6*AC6,"n/a"),"n/a") -> 0 | AE6: =IFERROR(AVERAGEIF('Pemetaan Variant'!$A$5:$A$32,$B6,'Pemetaan Variant'!$Y$5:$Y$32),"n/a") -> 12500 | AF6: =IFERROR(IF(ISNUMBER(AE6),(AE6-AVERAGEIF('Pemetaan Variant'!$A$5:$A$32,$B6,'Pemetaan Variant'!$F$5:$F$32))/AVERAGEIF('Pemetaan Variant'!$A$5:$A$32,$B6,'Pemetaan Variant'!$F$5:$F$32)*100,"n/a"),"n/a") -> 0 | AG6: =IFERROR(IF(ISNUMBER(AF6),$C6*AF6,"n/a"),"n/a") -> 0 | AH6: =IFERROR(AVERAGEIF('Pemetaan Variant'!$A$5:$A$32,$B6,'Pemetaan Variant'!$Z$5:$Z$32),"n/a") -> 12500 | AI6: =IFERROR(IF(ISNUMBER(AH6),(AH6-AVERAGEIF('Pemetaan Variant'!$A$5:$A$32,$B6,'Pemetaan Variant'!$F$5:$F$32))/AVERAGEIF('Pemetaan Variant'!$A$5:$A$32,$B6,'Pemetaan Variant'!$F$5:$F$32)*100,"n/a"),"n/a") -> 0 | AJ6: =IFERROR(IF(ISNUMBER(AI6),$C6*AI6,"n/a"),"n/a") -> 0 | AK6: =IFERROR(AVERAGEIF('Pemetaan Variant'!$A$5:$A$32,$B6,'Pemetaan Variant'!$AA$5:$AA$32),"n/a") -> 12500 | AL6: =IFERROR(IF(ISNUMBER(AK6),(AK6-AVERAGEIF('Pemetaan Variant'!$A$5:$A$32,$B6,'Pemetaan Variant'!$F$5:$F$32))/AVERAGEIF('Pemetaan Variant'!$A$5:$A$32,$B6,'Pemetaan Variant'!$F$5:$F$32)*100,"n/a"),"n/a") -> 0 | AM6: =IFERROR(IF(ISNUMBER(AL6),$C6*AL6,"n/a"),"n/a") -> 0 | AN6: =IFERROR(AVERAGEIF('Pemetaan Variant'!$A$5:$A$32,$B6,'Pemetaan Variant'!$AB$5:$AB$32),"n/a") -> 12500 | AO6: =IFERROR(IF(ISNUMBER(AN6),(AN6-AVERAGEIF('Pemetaan Variant'!$A$5:$A$32,$B6,'Pemetaan Variant'!$F$5:$F$32))/AVERAGEIF('Pemetaan Variant'!$A$5:$A$32,$B6,'Pemetaan Variant'!$F$5:$F$32)*100,"n/a"),"n/a") -> 0 | AP6: =IFERROR(IF(ISNUMBER(AO6),$C6*AO6,"n/a"),"n/a") -> 0 | AQ6: =IFERROR(AVERAGEIF('Pemetaan Variant'!$A$5:$A$32,$B6,'Pemetaan Variant'!$AC$5:$AC$32),"n/a") -> n/a | AR6: =IFERROR(IF(ISNUMBER(AQ6),(AQ6-AVERAGEIF('Pemetaan Variant'!$A$5:$A$32,$B6,'Pemetaan Variant'!$F$5:$F$32))/AVERAGEIF('Pemetaan Variant'!$A$5:$A$32,$B6,'Pemetaan Variant'!$F$5:$F$32)*100,"n/a"),"n/a") -> n/a | AS6: =IFERROR(IF(ISNUMBER(AR6),$C6*AR6,"n/a"),"n/a") -> n/a | AT6: =IFERROR(AVERAGEIF('Pemetaan Variant'!$A$5:$A$32,$B6,'Pemetaan Variant'!$AD$5:$AD$32),"n/a") -> n/a | AU6: =IFERROR(IF(ISNUMBER(AT6),(AT6-AVERAGEIF('Pemetaan Variant'!$A$5:$A$32,$B6,'Pemetaan Variant'!$G$5:$G$32))/AVERAGEIF('Pemetaan Variant'!$A$5:$A$32,$B6,'Pemetaan Variant'!$G$5:$G$32)*100,"n/a"),"n/a") -> n/a | AV6: =IFERROR(IF(ISNUMBER(AU6),$C6*AU6,"n/a"),"n/a") -> n/a | AW6: =IFERROR(AVERAGEIF('Pemetaan Variant'!$A$5:$A$32,$B6,'Pemetaan Variant'!$AE$5:$AE$32),"n/a") -> 12500 | AX6: =IFERROR(IF(ISNUMBER(AW6),(AW6-AVERAGEIF('Pemetaan Variant'!$A$5:$A$32,$B6,'Pemetaan Variant'!$G$5:$G$32))/AVERAGEIF('Pemetaan Variant'!$A$5:$A$32,$B6,'Pemetaan Variant'!$G$5:$G$32)*100,"n/a"),"n/a") -> 0 | AY6: =IFERROR(IF(ISNUMBER(AX6),$C6*AX6,"n/a"),"n/a") -> 0 | AZ6: =IFERROR(AVERAGEIF('Pemetaan Variant'!$A$5:$A$32,$B6,'Pemetaan Variant'!$AF$5:$AF$32),"n/a") -> 12500 | BA6: =IFERROR(IF(ISNUMBER(AZ6),(AZ6-AVERAGEIF('Pemetaan Variant'!$A$5:$A$32,$B6,'Pemetaan Variant'!$G$5:$G$32))/AVERAGEIF('Pemetaan Variant'!$A$5:$A$32,$B6,'Pemetaan Variant'!$G$5:$G$32)*100,"n/a"),"n/a") -> 0 | BB6: =IFERROR(IF(ISNUMBER(BA6),$C6*BA6,"n/a"),"n/a") -> 0 | BC6: =IFERROR(AVERAGEIF('Pemetaan Variant'!$A$5:$A$32,$B6,'Pemetaan Variant'!$AG$5:$AG$32),"n/a") -> 12500 | BD6: =IFERROR(IF(ISNUMBER(BC6),(BC6-AVERAGEIF('Pemetaan Variant'!$A$5:$A$32,$B6,'Pemetaan Variant'!$G$5:$G$32))/AVERAGEIF('Pemetaan Variant'!$A$5:$A$32,$B6,'Pemetaan Variant'!$G$5:$G$32)*100,"n/a"),"n/a") -> 0 | BE6: =IFERROR(IF(ISNUMBER(BD6),$C6*BD6,"n/a"),"n/a") -> 0 | BF6: =IFERROR(AVERAGEIF('Pemetaan Variant'!$A$5:$A$32,$B6,'Pemetaan Variant'!$AH$5:$AH$32),"n/a") -> 12500 | BG6: =IFERROR(IF(ISNUMBER(BF6),(BF6-AVERAGEIF('Pemetaan Variant'!$A$5:$A$32,$B6,'Pemetaan Variant'!$G$5:$G$32))/AVERAGEIF('Pemetaan Variant'!$A$5:$A$32,$B6,'Pemetaan Variant'!$G$5:$G$32)*100,"n/a"),"n/a") -> 0 | BH6: =IFERROR(IF(ISNUMBER(BG6),$C6*BG6,"n/a"),"n/a") -> 0 | BI6: =IFERROR(AVERAGEIF('Pemetaan Variant'!$A$5:$A$32,$B6,'Pemetaan Variant'!$AI$5:$AI$32),"n/a") -> 12500 | BJ6: =IFERROR(IF(ISNUMBER(BI6),(BI6-AVERAGEIF('Pemetaan Variant'!$A$5:$A$32,$B6,'Pemetaan Variant'!$H$5:$H$32))/AVERAGEIF('Pemetaan Variant'!$A$5:$A$32,$B6,'Pemetaan Variant'!$H$5:$H$32)*100,"n/a"),"n/a") -> 0 | BK6: =IFERROR(IF(ISNUMBER(BJ6),$C6*BJ6,"n/a"),"n/a") -> 0 | BL6: =IFERROR(AVERAGEIF('Pemetaan Variant'!$A$5:$A$32,$B6,'Pemetaan Variant'!$AJ$5:$AJ$32),"n/a") -> 12500 | BM6: =IFERROR(IF(ISNUMBER(BL6),(BL6-AVERAGEIF('Pemetaan Variant'!$A$5:$A$32,$B6,'Pemetaan Variant'!$H$5:$H$32))/AVERAGEIF('Pemetaan Variant'!$A$5:$A$32,$B6,'Pemetaan Variant'!$H$5:$H$32)*100,"n/a"),"n/a") -> 0 | BN6: =IFERROR(IF(ISNUMBER(BM6),$C6*BM6,"n/a"),"n/a") -> 0 | BO6: =IFERROR(AVERAGEIF('Pemetaan Variant'!$A$5:$A$32,$B6,'Pemetaan Variant'!$AK$5:$AK$32),"n/a") -> 12500 | BP6: =IFERROR(IF(ISNUMBER(BO6),(BO6-AVERAGEIF('Pemetaan Variant'!$A$5:$A$32,$B6,'Pemetaan Variant'!$H$5:$H$32))/AVERAGEIF('Pemetaan Variant'!$A$5:$A$32,$B6,'Pemetaan Variant'!$H$5:$H$32)*100,"n/a"),"n/a") -> 0 | BQ6: =IFERROR(IF(ISNUMBER(BP6),$C6*BP6,"n/a"),"n/a") -> 0 | BR6: =IFERROR(AVERAGEIF('Pemetaan Variant'!$A$5:$A$32,$B6,'Pemetaan Variant'!$AL$5:$AL$32),"n/a") -> 12500 | BS6: =IFERROR(IF(ISNUMBER(BR6),(BR6-AVERAGEIF('Pemetaan Variant'!$A$5:$A$32,$B6,'Pemetaan Variant'!$H$5:$H$32))/AVERAGEIF('Pemetaan Variant'!$A$5:$A$32,$B6,'Pemetaan Variant'!$H$5:$H$32)*100,"n/a"),"n/a") -> 0 | BT6: =IFERROR(IF(ISNUMBER(BS6),$C6*BS6,"n/a"),"n/a") -> 0 | BU6: =IFERROR(AVERAGEIF('Pemetaan Variant'!$A$5:$A$32,$B6,'Pemetaan Variant'!$AM$5:$AM$32),"n/a") -> 12500 | BV6: =IFERROR(IF(ISNUMBER(BU6),(BU6-AVERAGEIF('Pemetaan Variant'!$A$5:$A$32,$B6,'Pemetaan Variant'!$H$5:$H$32))/AVERAGEIF('Pemetaan Variant'!$A$5:$A$32,$B6,'Pemetaan Variant'!$H$5:$H$32)*100,"n/a"),"n/a") -> 0 | BW6: =IFERROR(IF(ISNUMBER(BV6),$C6*BV6,"n/a"),"n/a") -> 0 | BX6: =IFERROR(AVERAGEIF('Pemetaan Variant'!$A$5:$A$32,$B6,'Pemetaan Variant'!$AN$5:$AN$32),"n/a") -> 12500 | BY6: =IFERROR(IF(ISNUMBER(BX6),(BX6-AVERAGEIF('Pemetaan Variant'!$A$5:$A$32,$B6,'Pemetaan Variant'!$I$5:$I$32))/AVERAGEIF('Pemetaan Variant'!$A$5:$A$32,$B6,'Pemetaan Variant'!$I$5:$I$32)*100,"n/a"),"n/a") -> 0 | BZ6: =IFERROR(IF(ISNUMBER(BY6),$C6*BY6,"n/a"),"n/a") -> 0 | CA6: =IFERROR(AVERAGEIF('Pemetaan Variant'!$A$5:$A$32,$B6,'Pemetaan Variant'!$AO$5:$AO$32),"n/a") -> 12500 | CB6: =IFERROR(IF(ISNUMBER(CA6),(CA6-AVERAGEIF('Pemetaan Variant'!$A$5:$A$32,$B6,'Pemetaan Variant'!$I$5:$I$32))/AVERAGEIF('Pemetaan Variant'!$A$5:$A$32,$B6,'Pemetaan Variant'!$I$5:$I$32)*100,"n/a"),"n/a") -> 0 | CC6: =IFERROR(IF(ISNUMBER(CB6),$C6*CB6,"n/a"),"n/a") -> 0 | CD6: =IFERROR(AVERAGEIF('Pemetaan Variant'!$A$5:$A$32,$B6,'Pemetaan Variant'!$AP$5:$AP$32),"n/a") -> 12500 | CE6: =IFERROR(IF(ISNUMBER(CD6),(CD6-AVERAGEIF('Pemetaan Variant'!$A$5:$A$32,$B6,'Pemetaan Variant'!$I$5:$I$32))/AVERAGEIF('Pemetaan Variant'!$A$5:$A$32,$B6,'Pemetaan Variant'!$I$5:$I$32)*100,"n/a"),"n/a") -> 0 | CF6: =IFERROR(IF(ISNUMBER(CE6),$C6*CE6,"n/a"),"n/a") -> 0 | CG6: =IFERROR(AVERAGEIF('Pemetaan Variant'!$A$5:$A$32,$B6,'Pemetaan Variant'!$AQ$5:$AQ$32),"n/a") -> 12500 | CH6: =IFERROR(IF(ISNUMBER(CG6),(CG6-AVERAGEIF('Pemetaan Variant'!$A$5:$A$32,$B6,'Pemetaan Variant'!$I$5:$I$32))/AVERAGEIF('Pemetaan Variant'!$A$5:$A$32,$B6,'Pemetaan Variant'!$I$5:$I$32)*100,"n/a"),"n/a") -> 0 | CI6: =IFERROR(IF(ISNUMBER(CH6),$C6*CH6,"n/a"),"n/a") -> 0 | CJ6: =IFERROR(AVERAGEIF('Pemetaan Variant'!$A$5:$A$32,$B6,'Pemetaan Variant'!$AR$5:$AR$32),"n/a") -> 12500 | CK6: =IFERROR(IF(ISNUMBER(CJ6),(CJ6-AVERAGEIF('Pemetaan Variant'!$A$5:$A$32,$B6,'Pemetaan Variant'!$J$5:$J$32))/AVERAGEIF('Pemetaan Variant'!$A$5:$A$32,$B6,'Pemetaan Variant'!$J$5:$J$32)*100,"n/a"),"n/a") -> 0 | CL6: =IFERROR(IF(ISNUMBER(CK6),$C6*CK6,"n/a"),"n/a") -> 0 | CM6: =IFERROR(AVERAGEIF('Pemetaan Variant'!$A$5:$A$32,$B6,'Pemetaan Variant'!$AS$5:$AS$32),"n/a") -> 12500 | CN6: =IFERROR(IF(ISNUMBER(CM6),(CM6-AVERAGEIF('Pemetaan Variant'!$A$5:$A$32,$B6,'Pemetaan Variant'!$J$5:$J$32))/AVERAGEIF('Pemetaan Variant'!$A$5:$A$32,$B6,'Pemetaan Variant'!$J$5:$J$32)*100,"n/a"),"n/a") -> 0 | CO6: =IFERROR(IF(ISNUMBER(CN6),$C6*CN6,"n/a"),"n/a") -> 0 | CP6: =IFERROR(AVERAGEIF('Pemetaan Variant'!$A$5:$A$32,$B6,'Pemetaan Variant'!$AT$5:$AT$32),"n/a") -> 12500 | CQ6: =IFERROR(IF(ISNUMBER(CP6),(CP6-AVERAGEIF('Pemetaan Variant'!$A$5:$A$32,$B6,'Pemetaan Variant'!$J$5:$J$32))/AVERAGEIF('Pemetaan Variant'!$A$5:$A$32,$B6,'Pemetaan Variant'!$J$5:$J$32)*100,"n/a"),"n/a") -> 0 | CR6: =IFERROR(IF(ISNUMBER(CQ6),$C6*CQ6,"n/a"),"n/a") -> 0 | CS6: =IFERROR(AVERAGEIF('Pemetaan Variant'!$A$5:$A$32,$B6,'Pemetaan Variant'!$AU$5:$AU$32),"n/a") -> 13166.667 | CT6: =IFERROR(IF(ISNUMBER(CS6),(CS6-AVERAGEIF('Pemetaan Variant'!$A$5:$A$32,$B6,'Pemetaan Variant'!$J$5:$J$32))/AVERAGEIF('Pemetaan Variant'!$A$5:$A$32,$B6,'Pemetaan Variant'!$J$5:$J$32)*100,"n/a"),"n/a") -> 5.3333333 | CU6: =IFERROR(IF(ISNUMBER(CT6),$C6*CT6,"n/a"),"n/a") -> 0.66714164 | CV6: =IFERROR(AVERAGEIF('Pemetaan Variant'!$A$5:$A$32,$B6,'Pemetaan Variant'!$AV$5:$AV$32),"n/a") -> 13166.667 | CW6: =IFERROR(IF(ISNUMBER(CV6),(CV6-AVERAGEIF('Pemetaan Variant'!$A$5:$A$32,$B6,'Pemetaan Variant'!$J$5:$J$32))/AVERAGEIF('Pemetaan Variant'!$A$5:$A$32,$B6,'Pemetaan Variant'!$J$5:$J$32)*100,"n/a"),"n/a") -> 5.3333333 | CX6: =IFERROR(IF(ISNUMBER(CW6),$C6*CW6,"n/a"),"n/a") -> 0.66714164 | CY6: =IFERROR(AVERAGEIF('Pemetaan Variant'!$A$5:$A$32,$B6,'Pemetaan Variant'!$AW$5:$AW$32),"n/a") -> 0 | CZ6: =IFERROR(IF(ISNUMBER(CY6),(CY6-AVERAGEIF('Pemetaan Variant'!$A$5:$A$32,$B6,'Pemetaan Variant'!$K$5:$K$32))/AVERAGEIF('Pemetaan Variant'!$A$5:$A$32,$B6,'Pemetaan Variant'!$K$5:$K$32)*100,"n/a"),"n/a") -> -100 | DA6: =IFERROR(IF(ISNUMBER(CZ6),$C6*CZ6,"n/a"),"n/a") -> -12.508906 | DB6: =IFERROR(AVERAGEIF('Pemetaan Variant'!$A$5:$A$32,$B6,'Pemetaan Variant'!$AX$5:$AX$32),"n/a") -> 0 | DC6: =IFERROR(IF(ISNUMBER(DB6),(DB6-AVERAGEIF('Pemetaan Variant'!$A$5:$A$32,$B6,'Pemetaan Variant'!$K$5:$K$32))/AVERAGEIF('Pemetaan Variant'!$A$5:$A$32,$B6,'Pemetaan Variant'!$K$5:$K$32)*100,"n/a"),"n/a") -> -100 | DD6: =IFERROR(IF(ISNUMBER(DC6),$C6*DC6,"n/a"),"n/a") -> -12.508906 | DE6: =IFERROR(AVERAGEIF('Pemetaan Variant'!$A$5:$A$32,$B6,'Pemetaan Variant'!$AY$5:$AY$32),"n/a") -> 0 | DF6: =IFERROR(IF(ISNUMBER(DE6),(DE6-AVERAGEIF('Pemetaan Variant'!$A$5:$A$32,$B6,'Pemetaan Variant'!$K$5:$K$32))/AVERAGEIF('Pemetaan Variant'!$A$5:$A$32,$B6,'Pemetaan Variant'!$K$5:$K$32)*100,"n/a"),"n/a") -> -100 | DG6: =IFERROR(IF(ISNUMBER(DF6),$C6*DF6,"n/a"),"n/a") -> -12.508906 | DH6: =IFERROR(AVERAGEIF('Pemetaan Variant'!$A$5:$A$32,$B6,'Pemetaan Variant'!$AZ$5:$AZ$32),"n/a") -> 0 | DI6: =IFERROR(IF(ISNUMBER(DH6),(DH6-AVERAGEIF('Pemetaan Variant'!$A$5:$A$32,$B6,'Pemetaan Variant'!$K$5:$K$32))/AVERAGEIF('Pemetaan Variant'!$A$5:$A$32,$B6,'Pemetaan Variant'!$K$5:$K$32)*100,"n/a"),"n/a") -> -100 | DJ6: =IFERROR(IF(ISNUMBER(DI6),$C6*DI6,"n/a"),"n/a") -> -12.508906 | DK6: =IFERROR(AVERAGEIF('Pemetaan Variant'!$A$5:$A$32,$B6,'Pemetaan Variant'!$BA$5:$BA$32),"n/a") -> n/a | DL6: =IFERROR(IF(ISNUMBER(DK6),(DK6-AVERAGEIF('Pemetaan Variant'!$A$5:$A$32,$B6,'Pemetaan Variant'!$L$5:$L$32))/AVERAGEIF('Pemetaan Variant'!$A$5:$A$32,$B6,'Pemetaan Variant'!$L$5:$L$32)*100,"n/a"),"n/a") -> n/a | DM6: =IFERROR(IF(ISNUMBER(DL6),$C6*DL6,"n/a"),"n/a") -> n/a | DN6: =IFERROR(AVERAGEIF('Pemetaan Variant'!$A$5:$A$32,$B6,'Pemetaan Variant'!$BB$5:$BB$32),"n/a") -> n/a | DO6: =IFERROR(IF(ISNUMBER(DN6),(DN6-AVERAGEIF('Pemetaan Variant'!$A$5:$A$32,$B6,'Pemetaan Variant'!$L$5:$L$32))/AVERAGEIF('Pemetaan Variant'!$A$5:$A$32,$B6,'Pemetaan Variant'!$L$5:$L$32)*100,"n/a"),"n/a") -> n/a | DP6: =IFERROR(IF(ISNUMBER(DO6),$C6*DO6,"n/a"),"n/a") -> n/a | DQ6: =IFERROR(AVERAGEIF('Pemetaan Variant'!$A$5:$A$32,$B6,'Pemetaan Variant'!$BC$5:$BC$32),"n/a") -> n/a | DR6: =IFERROR(IF(ISNUMBER(DQ6),(DQ6-AVERAGEIF('Pemetaan Variant'!$A$5:$A$32,$B6,'Pemetaan Variant'!$L$5:$L$32))/AVERAGEIF('Pemetaan Variant'!$A$5:$A$32,$B6,'Pemetaan Variant'!$L$5:$L$32)*100,"n/a"),"n/a") -> n/a | DS6: =IFERROR(IF(ISNUMBER(DR6),$C6*DR6,"n/a"),"n/a") -> n/a | DT6: =IFERROR(AVERAGEIF('Pemetaan Variant'!$A$5:$A$32,$B6,'Pemetaan Variant'!$BD$5:$BD$32),"n/a") -> n/a | DU6: =IFERROR(IF(ISNUMBER(DT6),(DT6-AVERAGEIF('Pemetaan Variant'!$A$5:$A$32,$B6,'Pemetaan Variant'!$L$5:$L$32))/AVERAGEIF('Pemetaan Variant'!$A$5:$A$32,$B6,'Pemetaan Variant'!$L$5:$L$32)*100,"n/a"),"n/a") -> n/a | DV6: =IFERROR(IF(ISNUMBER(DU6),$C6*DU6,"n/a"),"n/a") -> n/a | DW6: =IFERROR(AVERAGEIF('Pemetaan Variant'!$A$5:$A$32,$B6,'Pemetaan Variant'!$BE$5:$BE$32),"n/a") -> n/a | DX6: =IFERROR(IF(ISNUMBER(DW6),(DW6-AVERAGEIF('Pemetaan Variant'!$A$5:$A$32,$B6,'Pemetaan Variant'!$M$5:$M$32))/AVERAGEIF('Pemetaan Variant'!$A$5:$A$32,$B6,'Pemetaan Variant'!$M$5:$M$32)*100,"n/a"),"n/a") -> n/a | DY6: =IFERROR(IF(ISNUMBER(DX6),$C6*DX6,"n/a"),"n/a") -> n/a | DZ6: =IFERROR(AVERAGEIF('Pemetaan Variant'!$A$5:$A$32,$B6,'Pemetaan Variant'!$BF$5:$BF$32),"n/a") -> n/a | EA6: =IFERROR(IF(ISNUMBER(DZ6),(DZ6-AVERAGEIF('Pemetaan Variant'!$A$5:$A$32,$B6,'Pemetaan Variant'!$M$5:$M$32))/AVERAGEIF('Pemetaan Variant'!$A$5:$A$32,$B6,'Pemetaan Variant'!$M$5:$M$32)*100,"n/a"),"n/a") -> n/a | EB6: =IFERROR(IF(ISNUMBER(EA6),$C6*EA6,"n/a"),"n/a") -> n/a | EC6: =IFERROR(AVERAGEIF('Pemetaan Variant'!$A$5:$A$32,$B6,'Pemetaan Variant'!$BG$5:$BG$32),"n/a") -> n/a | ED6: =IFERROR(IF(ISNUMBER(EC6),(EC6-AVERAGEIF('Pemetaan Variant'!$A$5:$A$32,$B6,'Pemetaan Variant'!$M$5:$M$32))/AVERAGEIF('Pemetaan Variant'!$A$5:$A$32,$B6,'Pemetaan Variant'!$M$5:$M$32)*100,"n/a"),"n/a") -> n/a | EE6: =IFERROR(IF(ISNUMBER(ED6),$C6*ED6,"n/a"),"n/a") -> n/a | EF6: =IFERROR(AVERAGEIF('Pemetaan Variant'!$A$5:$A$32,$B6,'Pemetaan Variant'!$BH$5:$BH$32),"n/a") -> n/a | EG6: =IFERROR(IF(ISNUMBER(EF6),(EF6-AVERAGEIF('Pemetaan Variant'!$A$5:$A$32,$B6,'Pemetaan Variant'!$M$5:$M$32))/AVERAGEIF('Pemetaan Variant'!$A$5:$A$32,$B6,'Pemetaan Variant'!$M$5:$M$32)*100,"n/a"),"n/a") -> n/a | EH6: =IFERROR(IF(ISNUMBER(EG6),$C6*EG6,"n/a"),"n/a") -> n/a | EI6: =IFERROR(AVERAGEIF('Pemetaan Variant'!$A$5:$A$32,$B6,'Pemetaan Variant'!$BI$5:$BI$32),"n/a") -> n/a | EJ6: =IFERROR(IF(ISNUMBER(EI6),(EI6-AVERAGEIF('Pemetaan Variant'!$A$5:$A$32,$B6,'Pemetaan Variant'!$M$5:$M$32))/AVERAGEIF('Pemetaan Variant'!$A$5:$A$32,$B6,'Pemetaan Variant'!$M$5:$M$32)*100,"n/a"),"n/a") -> n/a | EK6: =IFERROR(IF(ISNUMBER(EJ6),$C6*EJ6,"n/a"),"n/a") -> n/a | EL6: =IFERROR(AVERAGEIF('Pemetaan Variant'!$A$5:$A$32,$B6,'Pemetaan Variant'!$BJ$5:$BJ$32),"n/a") -> n/a | EM6: =IFERROR(IF(ISNUMBER(EL6),(EL6-AVERAGEIF('Pemetaan Variant'!$A$5:$A$32,$B6,'Pemetaan Variant'!$N$5:$N$32))/AVERAGEIF('Pemetaan Variant'!$A$5:$A$32,$B6,'Pemetaan Variant'!$N$5:$N$32)*100,"n/a"),"n/a") -> n/a | EN6: =IFERROR(IF(ISNUMBER(EM6),$C6*EM6,"n/a"),"n/a") -> n/a | EO6: =IFERROR(AVERAGEIF('Pemetaan Variant'!$A$5:$A$32,$B6,'Pemetaan Variant'!$BK$5:$BK$32),"n/a") -> n/a | EP6: =IFERROR(IF(ISNUMBER(EO6),(EO6-AVERAGEIF('Pemetaan Variant'!$A$5:$A$32,$B6,'Pemetaan Variant'!$N$5:$N$32))/AVERAGEIF('Pemetaan Variant'!$A$5:$A$32,$B6,'Pemetaan Variant'!$N$5:$N$32)*100,"n/a"),"n/a") -> n/a | EQ6: =IFERROR(IF(ISNUMBER(EP6),$C6*EP6,"n/a"),"n/a") -> n/a | ER6: =IFERROR(AVERAGEIF('Pemetaan Variant'!$A$5:$A$32,$B6,'Pemetaan Variant'!$BL$5:$BL$32),"n/a") -> n/a | ES6: =IFERROR(IF(ISNUMBER(ER6),(ER6-AVERAGEIF('Pemetaan Variant'!$A$5:$A$32,$B6,'Pemetaan Variant'!$N$5:$N$32))/AVERAGEIF('Pemetaan Variant'!$A$5:$A$32,$B6,'Pemetaan Variant'!$N$5:$N$32)*100,"n/a"),"n/a") -> n/a | ET6: =IFERROR(IF(ISNUMBER(ES6),$C6*ES6,"n/a"),"n/a") -> n/a | EU6: =IFERROR(AVERAGEIF('Pemetaan Variant'!$A$5:$A$32,$B6,'Pemetaan Variant'!$BM$5:$BM$32),"n/a") -> n/a | EV6: =IFERROR(IF(ISNUMBER(EU6),(EU6-AVERAGEIF('Pemetaan Variant'!$A$5:$A$32,$B6,'Pemetaan Variant'!$N$5:$N$32))/AVERAGEIF('Pemetaan Variant'!$A$5:$A$32,$B6,'Pemetaan Variant'!$N$5:$N$32)*100,"n/a"),"n/a") -> n/a | EW6: =IFERROR(IF(ISNUMBER(EV6),$C6*EV6,"n/a"),"n/a") -> n/a | EX6: =IFERROR(AVERAGEIF('Pemetaan Variant'!$A$5:$A$32,$B6,'Pemetaan Variant'!$BN$5:$BN$32),"n/a") -> n/a | EY6: =IFERROR(IF(ISNUMBER(EX6),(EX6-AVERAGEIF('Pemetaan Variant'!$A$5:$A$32,$B6,'Pemetaan Variant'!$O$5:$O$32))/AVERAGEIF('Pemetaan Variant'!$A$5:$A$32,$B6,'Pemetaan Variant'!$O$5:$O$32)*100,"n/a"),"n/a") -> n/a | EZ6: =IFERROR(IF(ISNUMBER(EY6),$C6*EY6,"n/a"),"n/a") -> n/a | FA6: =IFERROR(AVERAGEIF('Pemetaan Variant'!$A$5:$A$32,$B6,'Pemetaan Variant'!$BO$5:$BO$32),"n/a") -> n/a | FB6: =IFERROR(IF(ISNUMBER(FA6),(FA6-AVERAGEIF('Pemetaan Variant'!$A$5:$A$32,$B6,'Pemetaan Variant'!$O$5:$O$32))/AVERAGEIF('Pemetaan Variant'!$A$5:$A$32,$B6,'Pemetaan Variant'!$O$5:$O$32)*100,"n/a"),"n/a") -> n/a | FC6: =IFERROR(IF(ISNUMBER(FB6),$C6*FB6,"n/a"),"n/a") -> n/a | FD6: =IFERROR(AVERAGEIF('Pemetaan Variant'!$A$5:$A$32,$B6,'Pemetaan Variant'!$BP$5:$BP$32),"n/a") -> n/a | FE6: =IFERROR(IF(ISNUMBER(FD6),(FD6-AVERAGEIF('Pemetaan Variant'!$A$5:$A$32,$B6,'Pemetaan Variant'!$O$5:$O$32))/AVERAGEIF('Pemetaan Variant'!$A$5:$A$32,$B6,'Pemetaan Variant'!$O$5:$O$32)*100,"n/a"),"n/a") -> n/a | FF6: =IFERROR(IF(ISNUMBER(FE6),$C6*FE6,"n/a"),"n/a") -> n/a | FG6: =IFERROR(AVERAGEIF('Pemetaan Variant'!$A$5:$A$32,$B6,'Pemetaan Variant'!$BQ$5:$BQ$32),"n/a") -> n/a | FH6: =IFERROR(IF(ISNUMBER(FG6),(FG6-AVERAGEIF('Pemetaan Variant'!$A$5:$A$32,$B6,'Pemetaan Variant'!$O$5:$O$32))/AVERAGEIF('Pemetaan Variant'!$A$5:$A$32,$B6,'Pemetaan Variant'!$O$5:$O$32)*100,"n/a"),"n/a") -> n/a | FI6: =IFERROR(IF(ISNUMBER(FH6),$C6*FH6,"n/a"),"n/a") -> n/a | FJ6: =IFERROR(AVERAGEIF('Pemetaan Variant'!$A$5:$A$32,$B6,'Pemetaan Variant'!$BR$5:$BR$32),"n/a") -> n/a | FK6: =IFERROR(IF(ISNUMBER(FJ6),(FJ6-AVERAGEIF('Pemetaan Variant'!$A$5:$A$32,$B6,'Pemetaan Variant'!$O$5:$O$32))/AVERAGEIF('Pemetaan Variant'!$A$5:$A$32,$B6,'Pemetaan Variant'!$O$5:$O$32)*100,"n/a"),"n/a") -> n/a | FL6: =IFERROR(IF(ISNUMBER(FK6),$C6*FK6,"n/a"),"n/a") -> n/a | FO6: =IFERROR(ABS(F6),0) -> 0 | FP6: =IFERROR(ABS(I6),0) -> 0 | FQ6: =IFERROR(ABS(L6),0) -> 0 | FR6: =IFERROR(ABS(O6),0) -> 0 | FS6: =IFERROR(ABS(R6),0) -> 0 | FT6: =IFERROR(ABS(U6),0) -> 0 | FU6: =IFERROR(ABS(X6),0) -> 0 | FV6: =IFERROR(ABS(AA6),0) -> 0 | FW6: =IFERROR(ABS(AD6),0) -> 0 | FX6: =IFERROR(ABS(AG6),0) -> 0 | FY6: =IFERROR(ABS(AJ6),0) -> 0 | FZ6: =IFERROR(ABS(AM6),0) -> 0 | GA6: =IFERROR(ABS(AP6),0) -> 0 | GB6: =IFERROR(ABS(AS6),0) -> 0 | GC6: =IFERROR(ABS(AV6),0) -> 0 | GD6: =IFERROR(ABS(AY6),0) -> 0 | GE6: =IFERROR(ABS(BB6),0) -> 0 | GF6: =IFERROR(ABS(BE6),0) -> 0 | GG6: =IFERROR(ABS(BH6),0) -> 0 | GH6: =IFERROR(ABS(BK6),0) -> 0 | GI6: =IFERROR(ABS(BN6),0) -> 0 | GJ6: =IFERROR(ABS(BQ6),0) -> 0 | GK6: =IFERROR(ABS(BT6),0) -> 0 | GL6: =IFERROR(ABS(BW6),0) -> 0 | GM6: =IFERROR(ABS(BZ6),0) -> 0 | GN6: =IFERROR(ABS(CC6),0) -> 0 | GO6: =IFERROR(ABS(CF6),0) -> 0 | GP6: =IFERROR(ABS(CI6),0) -> 0 | GQ6: =IFERROR(ABS(CL6),0) -> 0 | GR6: =IFERROR(ABS(CO6),0) -> 0 | GS6: =IFERROR(ABS(CR6),0) -> 0 | GT6: =IFERROR(ABS(CU6),0) -> 0.66714164 | GU6: =IFERROR(ABS(CX6),0) -> 0.66714164 | GV6: =IFERROR(ABS(DA6),0) -> 12.508906 | GW6: =IFERROR(ABS(DD6),0) -> 12.508906 | GX6: =IFERROR(ABS(DG6),0) -> 12.508906 | GY6: =IFERROR(ABS(DJ6),0) -> 12.508906 | GZ6: =IFERROR(ABS(DM6),0) -> 0 | HA6: =IFERROR(ABS(DP6),0) -> 0 | HB6: =IFERROR(ABS(DS6),0) -> 0 | HC6: =IFERROR(ABS(DV6),0) -> 0 | HD6: =IFERROR(ABS(DY6),0) -> 0 | HE6: =IFERROR(ABS(EB6),0) -> 0 | HF6: =IFERROR(ABS(EE6),0) -> 0 | HG6: =IFERROR(ABS(EH6),0) -> 0 | HH6: =IFERROR(ABS(EK6),0) -> 0 | HI6: =IFERROR(ABS(EN6),0) -> 0 | HJ6: =IFERROR(ABS(EQ6),0) -> 0 | HK6: =IFERROR(ABS(ET6),0) -> 0 | HL6: =IFERROR(ABS(EW6),0) -> 0 | HM6: =IFERROR(ABS(EZ6),0) -> 0 | HN6: =IFERROR(ABS(FC6),0) -> 0 | HO6: =IFERROR(ABS(FF6),0) -> 0 | HP6: =IFERROR(ABS(FI6),0) -> 0 | HQ6: =IFERROR(ABS(FL6),0) -> 0
A7: 2 | B7: tepung terigu 01115005 | C7: ='P0Q0 Dasar 2022'!F6 -> 0.0079366405 | D7: =IFERROR(AVERAGEIF('Pemetaan Variant'!$A$5:$A$32,$B7,'Pemetaan Variant'!$P$5:$P$32),"n/a") -> 9500 | E7: =IFERROR(IF(ISNUMBER(D7),(D7-AVERAGEIF('Pemetaan Variant'!$A$5:$A$32,$B7,'Pemetaan Variant'!$D$5:$D$32))/AVERAGEIF('Pemetaan Variant'!$A$5:$A$32,$B7,'Pemetaan Variant'!$D$5:$D$32)*100,"n/a"),"n/a") -> 0 | F7: =IFERROR(IF(ISNUMBER(E7),$C7*E7,"n/a"),"n/a") -> 0 | G7: =IFERROR(AVERAGEIF('Pemetaan Variant'!$A$5:$A$32,$B7,'Pemetaan Variant'!$Q$5:$Q$32),"n/a") -> 9400 | H7: =IFERROR(IF(ISNUMBER(G7),(G7-AVERAGEIF('Pemetaan Variant'!$A$5:$A$32,$B7,'Pemetaan Variant'!$D$5:$D$32))/AVERAGEIF('Pemetaan Variant'!$A$5:$A$32,$B7,'Pemetaan Variant'!$D$5:$D$32)*100,"n/a"),"n/a") -> -1.0526316 | I7: =IFERROR(IF(ISNUMBER(H7),$C7*H7,"n/a"),"n/a") -> -0.0083543584 | J7: =IFERROR(AVERAGEIF('Pemetaan Variant'!$A$5:$A$32,$B7,'Pemetaan Variant'!$R$5:$R$32),"n/a") -> 9000 | K7: =IFERROR(IF(ISNUMBER(J7),(J7-AVERAGEIF('Pemetaan Variant'!$A$5:$A$32,$B7,'Pemetaan Variant'!$D$5:$D$32))/AVERAGEIF('Pemetaan Variant'!$A$5:$A$32,$B7,'Pemetaan Variant'!$D$5:$D$32)*100,"n/a"),"n/a") -> -5.2631579 | L7: =IFERROR(IF(ISNUMBER(K7),$C7*K7,"n/a"),"n/a") -> -0.041771792 | M7: =IFERROR(AVERAGEIF('Pemetaan Variant'!$A$5:$A$32,$B7,'Pemetaan Variant'!$S$5:$S$32),"n/a") -> 9000 | N7: =IFERROR(IF(ISNUMBER(M7),(M7-AVERAGEIF('Pemetaan Variant'!$A$5:$A$32,$B7,'Pemetaan Variant'!$D$5:$D$32))/AVERAGEIF('Pemetaan Variant'!$A$5:$A$32,$B7,'Pemetaan Variant'!$D$5:$D$32)*100,"n/a"),"n/a") -> -5.2631579 | O7: =IFERROR(IF(ISNUMBER(N7),$C7*N7,"n/a"),"n/a") -> -0.041771792 | P7: =IFERROR(AVERAGEIF('Pemetaan Variant'!$A$5:$A$32,$B7,'Pemetaan Variant'!$T$5:$T$32),"n/a") -> 9000 | Q7: =IFERROR(IF(ISNUMBER(P7),(P7-AVERAGEIF('Pemetaan Variant'!$A$5:$A$32,$B7,'Pemetaan Variant'!$D$5:$D$32))/AVERAGEIF('Pemetaan Variant'!$A$5:$A$32,$B7,'Pemetaan Variant'!$D$5:$D$32)*100,"n/a"),"n/a") -> -5.2631579 | R7: =IFERROR(IF(ISNUMBER(Q7),$C7*Q7,"n/a"),"n/a") -> -0.041771792 | S7: =IFERROR(AVERAGEIF('Pemetaan Variant'!$A$5:$A$32,$B7,'Pemetaan Variant'!$U$5:$U$32),"n/a") -> 9000 | T7: =IFERROR(IF(ISNUMBER(S7),(S7-AVERAGEIF('Pemetaan Variant'!$A$5:$A$32,$B7,'Pemetaan Variant'!$E$5:$E$32))/AVERAGEIF('Pemetaan Variant'!$A$5:$A$32,$B7,'Pemetaan Variant'!$E$5:$E$32)*100,"n/a"),"n/a") -> -1.7241379 | U7: =IFERROR(IF(ISNUMBER(T7),$C7*T7,"n/a"),"n/a") -> -0.013683863 | V7: =IFERROR(AVERAGEIF('Pemetaan Variant'!$A$5:$A$32,$B7,'Pemetaan Variant'!$V$5:$V$32),"n/a") -> 9000 | W7: =IFERROR(IF(ISNUMBER(V7),(V7-AVERAGEIF('Pemetaan Variant'!$A$5:$A$32,$B7,'Pemetaan Variant'!$E$5:$E$32))/AVERAGEIF('Pemetaan Variant'!$A$5:$A$32,$B7,'Pemetaan Variant'!$E$5:$E$32)*100,"n/a"),"n/a") -> -1.7241379 | X7: =IFERROR(IF(ISNUMBER(W7),$C7*W7,"n/a"),"n/a") -> -0.013683863 | Y7: =IFERROR(AVERAGEIF('Pemetaan Variant'!$A$5:$A$32,$B7,'Pemetaan Variant'!$W$5:$W$32),"n/a") -> 9000 | Z7: =IFERROR(IF(ISNUMBER(Y7),(Y7-AVERAGEIF('Pemetaan Variant'!$A$5:$A$32,$B7,'Pemetaan Variant'!$E$5:$E$32))/AVERAGEIF('Pemetaan Variant'!$A$5:$A$32,$B7,'Pemetaan Variant'!$E$5:$E$32)*100,"n/a"),"n/a") -> -1.7241379 | AA7: =IFERROR(IF(ISNUMBER(Z7),$C7*Z7,"n/a"),"n/a") -> -0.013683863 | AB7: =IFERROR(AVERAGEIF('Pemetaan Variant'!$A$5:$A$32,$B7,'Pemetaan Variant'!$X$5:$X$32),"n/a") -> 9000 | AC7: =IFERROR(IF(ISNUMBER(AB7),(AB7-AVERAGEIF('Pemetaan Variant'!$A$5:$A$32,$B7,'Pemetaan Variant'!$E$5:$E$32))/AVERAGEIF('Pemetaan Variant'!$A$5:$A$32,$B7,'Pemetaan Variant'!$E$5:$E$32)*100,"n/a"),"n/a") -> -1.7241379 | AD7: =IFERROR(IF(ISNUMBER(AC7),$C7*AC7,"n/a"),"n/a") -> -0.013683863 | AE7: =IFERROR(AVERAGEIF('Pemetaan Variant'!$A$5:$A$32,$B7,'Pemetaan Variant'!$Y$5:$Y$32),"n/a") -> 9000 | AF7: =IFERROR(IF(ISNUMBER(AE7),(AE7-AVERAGEIF('Pemetaan Variant'!$A$5:$A$32,$B7,'Pemetaan Variant'!$F$5:$F$32))/AVERAGEIF('Pemetaan Variant'!$A$5:$A$32,$B7,'Pemetaan Variant'!$F$5:$F$32)*100,"n/a"),"n/a") -> 0 | AG7: =IFERROR(IF(ISNUMBER(AF7),$C7*AF7,"n/a"),"n/a") -> 0 | AH7: =IFERROR(AVERAGEIF('Pemetaan Variant'!$A$5:$A$32,$B7,'Pemetaan Variant'!$Z$5:$Z$32),"n/a") -> 9000 | AI7: =IFERROR(IF(ISNUMBER(AH7),(AH7-AVERAGEIF('Pemetaan Variant'!$A$5:$A$32,$B7,'Pemetaan Variant'!$F$5:$F$32))/AVERAGEIF('Pemetaan Variant'!$A$5:$A$32,$B7,'Pemetaan Variant'!$F$5:$F$32)*100,"n/a"),"n/a") -> 0 | AJ7: =IFERROR(IF(ISNUMBER(AI7),$C7*AI7,"n/a"),"n/a") -> 0 | AK7: =IFERROR(AVERAGEIF('Pemetaan Variant'!$A$5:$A$32,$B7,'Pemetaan Variant'!$AA$5:$AA$32),"n/a") -> 9000 | AL7: =IFERROR(IF(ISNUMBER(AK7),(AK7-AVERAGEIF('Pemetaan Variant'!$A$5:$A$32,$B7,'Pemetaan Variant'!$F$5:$F$32))/AVERAGEIF('Pemetaan Variant'!$A$5:$A$32,$B7,'Pemetaan Variant'!$F$5:$F$32)*100,"n/a"),"n/a") -> 0 | AM7: =IFERROR(IF(ISNUMBER(AL7),$C7*AL7,"n/a"),"n/a") -> 0 | AN7: =IFERROR(AVERAGEIF('Pemetaan Variant'!$A$5:$A$32,$B7,'Pemetaan Variant'!$AB$5:$AB$32),"n/a") -> 9000 | AO7: =IFERROR(IF(ISNUMBER(AN7),(AN7-AVERAGEIF('Pemetaan Variant'!$A$5:$A$32,$B7,'Pemetaan Variant'!$F$5:$F$32))/AVERAGEIF('Pemetaan Variant'!$A$5:$A$32,$B7,'Pemetaan Variant'!$F$5:$F$32)*100,"n/a"),"n/a") -> 0 | AP7: =IFERROR(IF(ISNUMBER(AO7),$C7*AO7,"n/a"),"n/a") -> 0 | AQ7: =IFERROR(AVERAGEIF('Pemetaan Variant'!$A$5:$A$32,$B7,'Pemetaan Variant'!$AC$5:$AC$32),"n/a") -> n/a | AR7: =IFERROR(IF(ISNUMBER(AQ7),(AQ7-AVERAGEIF('Pemetaan Variant'!$A$5:$A$32,$B7,'Pemetaan Variant'!$F$5:$F$32))/AVERAGEIF('Pemetaan Variant'!$A$5:$A$32,$B7,'Pemetaan Variant'!$F$5:$F$32)*100,"n/a"),"n/a") -> n/a | AS7: =IFERROR(IF(ISNUMBER(AR7),$C7*AR7,"n/a"),"n/a") -> n/a | AT7: =IFERROR(AVERAGEIF('Pemetaan Variant'!$A$5:$A$32,$B7,'Pemetaan Variant'!$AD$5:$AD$32),"n/a") -> n/a | AU7: =IFERROR(IF(ISNUMBER(AT7),(AT7-AVERAGEIF('Pemetaan Variant'!$A$5:$A$32,$B7,'Pemetaan Variant'!$G$5:$G$32))/AVERAGEIF('Pemetaan Variant'!$A$5:$A$32,$B7,'Pemetaan Variant'!$G$5:$G$32)*100,"n/a"),"n/a") -> n/a | AV7: =IFERROR(IF(ISNUMBER(AU7),$C7*AU7,"n/a"),"n/a") -> n/a | AW7: =IFERROR(AVERAGEIF('Pemetaan Variant'!$A$5:$A$32,$B7,'Pemetaan Variant'!$AE$5:$AE$32),"n/a") -> 9000 | AX7: =IFERROR(IF(ISNUMBER(AW7),(AW7-AVERAGEIF('Pemetaan Variant'!$A$5:$A$32,$B7,'Pemetaan Variant'!$G$5:$G$32))/AVERAGEIF('Pemetaan Variant'!$A$5:$A$32,$B7,'Pemetaan Variant'!$G$5:$G$32)*100,"n/a"),"n/a") -> 0 | AY7: =IFERROR(IF(ISNUMBER(AX7),$C7*AX7,"n/a"),"n/a") -> 0 | AZ7: =IFERROR(AVERAGEIF('Pemetaan Variant'!$A$5:$A$32,$B7,'Pemetaan Variant'!$AF$5:$AF$32),"n/a") -> 9000 | BA7: =IFERROR(IF(ISNUMBER(AZ7),(AZ7-AVERAGEIF('Pemetaan Variant'!$A$5:$A$32,$B7,'Pemetaan Variant'!$G$5:$G$32))/AVERAGEIF('Pemetaan Variant'!$A$5:$A$32,$B7,'Pemetaan Variant'!$G$5:$G$32)*100,"n/a"),"n/a") -> 0 | BB7: =IFERROR(IF(ISNUMBER(BA7),$C7*BA7,"n/a"),"n/a") -> 0 | BC7: =IFERROR(AVERAGEIF('Pemetaan Variant'!$A$5:$A$32,$B7,'Pemetaan Variant'!$AG$5:$AG$32),"n/a") -> 9000 | BD7: =IFERROR(IF(ISNUMBER(BC7),(BC7-AVERAGEIF('Pemetaan Variant'!$A$5:$A$32,$B7,'Pemetaan Variant'!$G$5:$G$32))/AVERAGEIF('Pemetaan Variant'!$A$5:$A$32,$B7,'Pemetaan Variant'!$G$5:$G$32)*100,"n/a"),"n/a") -> 0 | BE7: =IFERROR(IF(ISNUMBER(BD7),$C7*BD7,"n/a"),"n/a") -> 0 | BF7: =IFERROR(AVERAGEIF('Pemetaan Variant'!$A$5:$A$32,$B7,'Pemetaan Variant'!$AH$5:$AH$32),"n/a") -> 9000 | BG7: =IFERROR(IF(ISNUMBER(BF7),(BF7-AVERAGEIF('Pemetaan Variant'!$A$5:$A$32,$B7,'Pemetaan Variant'!$G$5:$G$32))/AVERAGEIF('Pemetaan Variant'!$A$5:$A$32,$B7,'Pemetaan Variant'!$G$5:$G$32)*100,"n/a"),"n/a") -> 0 | BH7: =IFERROR(IF(ISNUMBER(BG7),$C7*BG7,"n/a"),"n/a") -> 0 | BI7: =IFERROR(AVERAGEIF('Pemetaan Variant'!$A$5:$A$32,$B7,'Pemetaan Variant'!$AI$5:$AI$32),"n/a") -> 9000 | BJ7: =IFERROR(IF(ISNUMBER(BI7),(BI7-AVERAGEIF('Pemetaan Variant'!$A$5:$A$32,$B7,'Pemetaan Variant'!$H$5:$H$32))/AVERAGEIF('Pemetaan Variant'!$A$5:$A$32,$B7,'Pemetaan Variant'!$H$5:$H$32)*100,"n/a"),"n/a") -> 0 | BK7: =IFERROR(IF(ISNUMBER(BJ7),$C7*BJ7,"n/a"),"n/a") -> 0 | BL7: =IFERROR(AVERAGEIF('Pemetaan Variant'!$A$5:$A$32,$B7,'Pemetaan Variant'!$AJ$5:$AJ$32),"n/a") -> 9000 | BM7: =IFERROR(IF(ISNUMBER(BL7),(BL7-AVERAGEIF('Pemetaan Variant'!$A$5:$A$32,$B7,'Pemetaan Variant'!$H$5:$H$32))/AVERAGEIF('Pemetaan Variant'!$A$5:$A$32,$B7,'Pemetaan Variant'!$H$5:$H$32)*100,"n/a"),"n/a") -> 0 | BN7: =IFERROR(IF(ISNUMBER(BM7),$C7*BM7,"n/a"),"n/a") -> 0 | BO7: =IFERROR(AVERAGEIF('Pemetaan Variant'!$A$5:$A$32,$B7,'Pemetaan Variant'!$AK$5:$AK$32),"n/a") -> 9000 | BP7: =IFERROR(IF(ISNUMBER(BO7),(BO7-AVERAGEIF('Pemetaan Variant'!$A$5:$A$32,$B7,'Pemetaan Variant'!$H$5:$H$32))/AVERAGEIF('Pemetaan Variant'!$A$5:$A$32,$B7,'Pemetaan Variant'!$H$5:$H$32)*100,"n/a"),"n/a") -> 0 | BQ7: =IFERROR(IF(ISNUMBER(BP7),$C7*BP7,"n/a"),"n/a") -> 0 | BR7: =IFERROR(AVERAGEIF('Pemetaan Variant'!$A$5:$A$32,$B7,'Pemetaan Variant'!$AL$5:$AL$32),"n/a") -> 9000 | BS7: =IFERROR(IF(ISNUMBER(BR7),(BR7-AVERAGEIF('Pemetaan Variant'!$A$5:$A$32,$B7,'Pemetaan Variant'!$H$5:$H$32))/AVERAGEIF('Pemetaan Variant'!$A$5:$A$32,$B7,'Pemetaan Variant'!$H$5:$H$32)*100,"n/a"),"n/a") -> 0 | BT7: =IFERROR(IF(ISNUMBER(BS7),$C7*BS7,"n/a"),"n/a") -> 0 | BU7: =IFERROR(AVERAGEIF('Pemetaan Variant'!$A$5:$A$32,$B7,'Pemetaan Variant'!$AM$5:$AM$32),"n/a") -> 9000 | BV7: =IFERROR(IF(ISNUMBER(BU7),(BU7-AVERAGEIF('Pemetaan Variant'!$A$5:$A$32,$B7,'Pemetaan Variant'!$H$5:$H$32))/AVERAGEIF('Pemetaan Variant'!$A$5:$A$32,$B7,'Pemetaan Variant'!$H$5:$H$32)*100,"n/a"),"n/a") -> 0 | BW7: =IFERROR(IF(ISNUMBER(BV7),$C7*BV7,"n/a"),"n/a") -> 0 | BX7: =IFERROR(AVERAGEIF('Pemetaan Variant'!$A$5:$A$32,$B7,'Pemetaan Variant'!$AN$5:$AN$32),"n/a") -> 9000 | BY7: =IFERROR(IF(ISNUMBER(BX7),(BX7-AVERAGEIF('Pemetaan Variant'!$A$5:$A$32,$B7,'Pemetaan Variant'!$I$5:$I$32))/AVERAGEIF('Pemetaan Variant'!$A$5:$A$32,$B7,'Pemetaan Variant'!$I$5:$I$32)*100,"n/a"),"n/a") -> 0 | BZ7: =IFERROR(IF(ISNUMBER(BY7),$C7*BY7,"n/a"),"n/a") -> 0 | CA7: =IFERROR(AVERAGEIF('Pemetaan Variant'!$A$5:$A$32,$B7,'Pemetaan Variant'!$AO$5:$AO$32),"n/a") -> 9000 | CB7: =IFERROR(IF(ISNUMBER(CA7),(CA7-AVERAGEIF('Pemetaan Variant'!$A$5:$A$32,$B7,'Pemetaan Variant'!$I$5:$I$32))/AVERAGEIF('Pemetaan Variant'!$A$5:$A$32,$B7,'Pemetaan Variant'!$I$5:$I$32)*100,"n/a"),"n/a") -> 0 | CC7: =IFERROR(IF(ISNUMBER(CB7),$C7*CB7,"n/a"),"n/a") -> 0 | CD7: =IFERROR(AVERAGEIF('Pemetaan Variant'!$A$5:$A$32,$B7,'Pemetaan Variant'!$AP$5:$AP$32),"n/a") -> 9000 | CE7: =IFERROR(IF(ISNUMBER(CD7),(CD7-AVERAGEIF('Pemetaan Variant'!$A$5:$A$32,$B7,'Pemetaan Variant'!$I$5:$I$32))/AVERAGEIF('Pemetaan Variant'!$A$5:$A$32,$B7,'Pemetaan Variant'!$I$5:$I$32)*100,"n/a"),"n/a") -> 0 | CF7: =IFERROR(IF(ISNUMBER(CE7),$C7*CE7,"n/a"),"n/a") -> 0 | CG7: =IFERROR(AVERAGEIF('Pemetaan Variant'!$A$5:$A$32,$B7,'Pemetaan Variant'!$AQ$5:$AQ$32),"n/a") -> 11375 | CH7: =IFERROR(IF(ISNUMBER(CG7),(CG7-AVERAGEIF('Pemetaan Variant'!$A$5:$A$32,$B7,'Pemetaan Variant'!$I$5:$I$32))/AVERAGEIF('Pemetaan Variant'!$A$5:$A$32,$B7,'Pemetaan Variant'!$I$5:$I$32)*100,"n/a"),"n/a") -> 26.388889 | CI7: =IFERROR(IF(ISNUMBER(CH7),$C7*CH7,"n/a"),"n/a") -> 0.20943912 | CJ7: =IFERROR(AVERAGEIF('Pemetaan Variant'!$A$5:$A$32,$B7,'Pemetaan Variant'!$AR$5:$AR$32),"n/a") -> 11500 | CK7: =IFERROR(IF(ISNUMBER(CJ7),(CJ7-AVERAGEIF('Pemetaan Variant'!$A$5:$A$32,$B7,'Pemetaan Variant'!$J$5:$J$32))/AVERAGEIF('Pemetaan Variant'!$A$5:$A$32,$B7,'Pemetaan Variant'!$J$5:$J$32)*100,"n/a"),"n/a") -> 20.307692 | CL7: =IFERROR(IF(ISNUMBER(CK7),$C7*CK7,"n/a"),"n/a") -> 0.16117485 | CM7: =IFERROR(AVERAGEIF('Pemetaan Variant'!$A$5:$A$32,$B7,'Pemetaan Variant'!$AS$5:$AS$32),"n/a") -> 11500 | CN7: =IFERROR(IF(ISNUMBER(CM7),(CM7-AVERAGEIF('Pemetaan Variant'!$A$5:$A$32,$B7,'Pemetaan Variant'!$J$5:$J$32))/AVERAGEIF('Pemetaan Variant'!$A$5:$A$32,$B7,'Pemetaan Variant'!$J$5:$J$32)*100,"n/a"),"n/a") -> 20.307692 | CO7: =IFERROR(IF(ISNUMBER(CN7),$C7*CN7,"n/a"),"n/a") -> 0.16117485 | CP7: =IFERROR(AVERAGEIF('Pemetaan Variant'!$A$5:$A$32,$B7,'Pemetaan Variant'!$AT$5:$AT$32),"n/a") -> 11500 | CQ7: =IFERROR(IF(ISNUMBER(CP7),(CP7-AVERAGEIF('Pemetaan Variant'!$A$5:$A$32,$B7,'Pemetaan Variant'!$J$5:$J$32))/AVERAGEIF('Pemetaan Variant'!$A$5:$A$32,$B7,'Pemetaan Variant'!$J$5:$J$32)*100,"n/a"),"n/a") -> 20.307692 | CR7: =IFERROR(IF(ISNUMBER(CQ7),$C7*CQ7,"n/a"),"n/a") -> 0.16117485 | CS7: =IFERROR(AVERAGEIF('Pemetaan Variant'!$A$5:$A$32,$B7,'Pemetaan Variant'!$AU$5:$AU$32),"n/a") -> 11500 | CT7: =IFERROR(IF(ISNUMBER(CS7),(CS7-AVERAGEIF('Pemetaan Variant'!$A$5:$A$32,$B7,'Pemetaan Variant'!$J$5:$J$32))/AVERAGEIF('Pemetaan Variant'!$A$5:$A$32,$B7,'Pemetaan Variant'!$J$5:$J$32)*100,"n/a"),"n/a") -> 20.307692 | CU7: =IFERROR(IF(ISNUMBER(CT7),$C7*CT7,"n/a"),"n/a") -> 0.16117485 | CV7: =IFERROR(AVERAGEIF('Pemetaan Variant'!$A$5:$A$32,$B7,'Pemetaan Variant'!$AV$5:$AV$32),"n/a") -> 11500 | CW7: =IFERROR(IF(ISNUMBER(CV7),(CV7-AVERAGEIF('Pemetaan Variant'!$A$5:$A$32,$B7,'Pemetaan Variant'!$J$5:$J$32))/AVERAGEIF('Pemetaan Variant'!$A$5:$A$32,$B7,'Pemetaan Variant'!$J$5:$J$32)*100,"n/a"),"n/a") -> 20.307692 | CX7: =IFERROR(IF(ISNUMBER(CW7),$C7*CW7,"n/a"),"n/a") -> 0.16117485 | CY7: =IFERROR(AVERAGEIF('Pemetaan Variant'!$A$5:$A$32,$B7,'Pemetaan Variant'!$AW$5:$AW$32),"n/a") -> 0 | CZ7: =IFERROR(IF(ISNUMBER(CY7),(CY7-AVERAGEIF('Pemetaan Variant'!$A$5:$A$32,$B7,'Pemetaan Variant'!$K$5:$K$32))/AVERAGEIF('Pemetaan Variant'!$A$5:$A$32,$B7,'Pemetaan Variant'!$K$5:$K$32)*100,"n/a"),"n/a") -> -100 | DA7: =IFERROR(IF(ISNUMBER(CZ7),$C7*CZ7,"n/a"),"n/a") -> -0.79366405 | DB7: =IFERROR(AVERAGEIF('Pemetaan Variant'!$A$5:$A$32,$B7,'Pemetaan Variant'!$AX$5:$AX$32),"n/a") -> 0 | DC7: =IFERROR(IF(ISNUMBER(DB7),(DB7-AVERAGEIF('Pemetaan Variant'!$A$5:$A$32,$B7,'Pemetaan Variant'!$K$5:$K$32))/AVERAGEIF('Pemetaan Variant'!$A$5:$A$32,$B7,'Pemetaan Variant'!$K$5:$K$32)*100,"n/a"),"n/a") -> -100 | DD7: =IFERROR(IF(ISNUMBER(DC7),$C7*DC7,"n/a"),"n/a") -> -0.79366405 | DE7: =IFERROR(AVERAGEIF('Pemetaan Variant'!$A$5:$A$32,$B7,'Pemetaan Variant'!$AY$5:$AY$32),"n/a") -> 0 | DF7: =IFERROR(IF(ISNUMBER(DE7),(DE7-AVERAGEIF('Pemetaan Variant'!$A$5:$A$32,$B7,'Pemetaan Variant'!$K$5:$K$32))/AVERAGEIF('Pemetaan Variant'!$A$5:$A$32,$B7,'Pemetaan Variant'!$K$5:$K$32)*100,"n/a"),"n/a") -> -100 | DG7: =IFERROR(IF(ISNUMBER(DF7),$C7*DF7,"n/a"),"n/a") -> -0.79366405 | DH7: =IFERROR(AVERAGEIF('Pemetaan Variant'!$A$5:$A$32,$B7,'Pemetaan Variant'!$AZ$5:$AZ$32),"n/a") -> 0 | DI7: =IFERROR(IF(ISNUMBER(DH7),(DH7-AVERAGEIF('Pemetaan Variant'!$A$5:$A$32,$B7,'Pemetaan Variant'!$K$5:$K$32))/AVERAGEIF('Pemetaan Variant'!$A$5:$A$32,$B7,'Pemetaan Variant'!$K$5:$K$32)*100,"n/a"),"n/a") -> -100 | DJ7: =IFERROR(IF(ISNUMBER(DI7),$C7*DI7,"n/a"),"n/a") -> -0.79366405 | DK7: =IFERROR(AVERAGEIF('Pemetaan Variant'!$A$5:$A$32,$B7,'Pemetaan Variant'!$BA$5:$BA$32),"n/a") -> n/a | DL7: =IFERROR(IF(ISNUMBER(DK7),(DK7-AVERAGEIF('Pemetaan Variant'!$A$5:$A$32,$B7,'Pemetaan Variant'!$L$5:$L$32))/AVERAGEIF('Pemetaan Variant'!$A$5:$A$32,$B7,'Pemetaan Variant'!$L$5:$L$32)*100,"n/a"),"n/a") -> n/a | DM7: =IFERROR(IF(ISNUMBER(DL7),$C7*DL7,"n/a"),"n/a") -> n/a | DN7: =IFERROR(AVERAGEIF('Pemetaan Variant'!$A$5:$A$32,$B7,'Pemetaan Variant'!$BB$5:$BB$32),"n/a") -> n/a | DO7: =IFERROR(IF(ISNUMBER(DN7),(DN7-AVERAGEIF('Pemetaan Variant'!$A$5:$A$32,$B7,'Pemetaan Variant'!$L$5:$L$32))/AVERAGEIF('Pemetaan Variant'!$A$5:$A$32,$B7,'Pemetaan Variant'!$L$5:$L$32)*100,"n/a"),"n/a") -> n/a | DP7: =IFERROR(IF(ISNUMBER(DO7),$C7*DO7,"n/a"),"n/a") -> n/a | DQ7: =IFERROR(AVERAGEIF('Pemetaan Variant'!$A$5:$A$32,$B7,'Pemetaan Variant'!$BC$5:$BC$32),"n/a") -> n/a | DR7: =IFERROR(IF(ISNUMBER(DQ7),(DQ7-AVERAGEIF('Pemetaan Variant'!$A$5:$A$32,$B7,'Pemetaan Variant'!$L$5:$L$32))/AVERAGEIF('Pemetaan Variant'!$A$5:$A$32,$B7,'Pemetaan Variant'!$L$5:$L$32)*100,"n/a"),"n/a") -> n/a | DS7: =IFERROR(IF(ISNUMBER(DR7),$C7*DR7,"n/a"),"n/a") -> n/a | DT7: =IFERROR(AVERAGEIF('Pemetaan Variant'!$A$5:$A$32,$B7,'Pemetaan Variant'!$BD$5:$BD$32),"n/a") -> n/a | DU7: =IFERROR(IF(ISNUMBER(DT7),(DT7-AVERAGEIF('Pemetaan Variant'!$A$5:$A$32,$B7,'Pemetaan Variant'!$L$5:$L$32))/AVERAGEIF('Pemetaan Variant'!$A$5:$A$32,$B7,'Pemetaan Variant'!$L$5:$L$32)*100,"n/a"),"n/a") -> n/a | DV7: =IFERROR(IF(ISNUMBER(DU7),$C7*DU7,"n/a"),"n/a") -> n/a | DW7: =IFERROR(AVERAGEIF('Pemetaan Variant'!$A$5:$A$32,$B7,'Pemetaan Variant'!$BE$5:$BE$32),"n/a") -> n/a | DX7: =IFERROR(IF(ISNUMBER(DW7),(DW7-AVERAGEIF('Pemetaan Variant'!$A$5:$A$32,$B7,'Pemetaan Variant'!$M$5:$M$32))/AVERAGEIF('Pemetaan Variant'!$A$5:$A$32,$B7,'Pemetaan Variant'!$M$5:$M$32)*100,"n/a"),"n/a") -> n/a | DY7: =IFERROR(IF(ISNUMBER(DX7),$C7*DX7,"n/a"),"n/a") -> n/a | DZ7: =IFERROR(AVERAGEIF('Pemetaan Variant'!$A$5:$A$32,$B7,'Pemetaan Variant'!$BF$5:$BF$32),"n/a") -> n/a | EA7: =IFERROR(IF(ISNUMBER(DZ7),(DZ7-AVERAGEIF('Pemetaan Variant'!$A$5:$A$32,$B7,'Pemetaan Variant'!$M$5:$M$32))/AVERAGEIF('Pemetaan Variant'!$A$5:$A$32,$B7,'Pemetaan Variant'!$M$5:$M$32)*100,"n/a"),"n/a") -> n/a | EB7: =IFERROR(IF(ISNUMBER(EA7),$C7*EA7,"n/a"),"n/a") -> n/a | EC7: =IFERROR(AVERAGEIF('Pemetaan Variant'!$A$5:$A$32,$B7,'Pemetaan Variant'!$BG$5:$BG$32),"n/a") -> n/a | ED7: =IFERROR(IF(ISNUMBER(EC7),(EC7-AVERAGEIF('Pemetaan Variant'!$A$5:$A$32,$B7,'Pemetaan Variant'!$M$5:$M$32))/AVERAGEIF('Pemetaan Variant'!$A$5:$A$32,$B7,'Pemetaan Variant'!$M$5:$M$32)*100,"n/a"),"n/a") -> n/a | EE7: =IFERROR(IF(ISNUMBER(ED7),$C7*ED7,"n/a"),"n/a") -> n/a | EF7: =IFERROR(AVERAGEIF('Pemetaan Variant'!$A$5:$A$32,$B7,'Pemetaan Variant'!$BH$5:$BH$32),"n/a") -> n/a | EG7: =IFERROR(IF(ISNUMBER(EF7),(EF7-AVERAGEIF('Pemetaan Variant'!$A$5:$A$32,$B7,'Pemetaan Variant'!$M$5:$M$32))/AVERAGEIF('Pemetaan Variant'!$A$5:$A$32,$B7,'Pemetaan Variant'!$M$5:$M$32)*100,"n/a"),"n/a") -> n/a | EH7: =IFERROR(IF(ISNUMBER(EG7),$C7*EG7,"n/a"),"n/a") -> n/a | EI7: =IFERROR(AVERAGEIF('Pemetaan Variant'!$A$5:$A$32,$B7,'Pemetaan Variant'!$BI$5:$BI$32),"n/a") -> n/a | EJ7: =IFERROR(IF(ISNUMBER(EI7),(EI7-AVERAGEIF('Pemetaan Variant'!$A$5:$A$32,$B7,'Pemetaan Variant'!$M$5:$M$32))/AVERAGEIF('Pemetaan Variant'!$A$5:$A$32,$B7,'Pemetaan Variant'!$M$5:$M$32)*100,"n/a"),"n/a") -> n/a | EK7: =IFERROR(IF(ISNUMBER(EJ7),$C7*EJ7,"n/a"),"n/a") -> n/a | EL7: =IFERROR(AVERAGEIF('Pemetaan Variant'!$A$5:$A$32,$B7,'Pemetaan Variant'!$BJ$5:$BJ$32),"n/a") -> n/a | EM7: =IFERROR(IF(ISNUMBER(EL7),(EL7-AVERAGEIF('Pemetaan Variant'!$A$5:$A$32,$B7,'Pemetaan Variant'!$N$5:$N$32))/AVERAGEIF('Pemetaan Variant'!$A$5:$A$32,$B7,'Pemetaan Variant'!$N$5:$N$32)*100,"n/a"),"n/a") -> n/a | EN7: =IFERROR(IF(ISNUMBER(EM7),$C7*EM7,"n/a"),"n/a") -> n/a | EO7: =IFERROR(AVERAGEIF('Pemetaan Variant'!$A$5:$A$32,$B7,'Pemetaan Variant'!$BK$5:$BK$32),"n/a") -> n/a | EP7: =IFERROR(IF(ISNUMBER(EO7),(EO7-AVERAGEIF('Pemetaan Variant'!$A$5:$A$32,$B7,'Pemetaan Variant'!$N$5:$N$32))/AVERAGEIF('Pemetaan Variant'!$A$5:$A$32,$B7,'Pemetaan Variant'!$N$5:$N$32)*100,"n/a"),"n/a") -> n/a | EQ7: =IFERROR(IF(ISNUMBER(EP7),$C7*EP7,"n/a"),"n/a") -> n/a | ER7: =IFERROR(AVERAGEIF('Pemetaan Variant'!$A$5:$A$32,$B7,'Pemetaan Variant'!$BL$5:$BL$32),"n/a") -> n/a | ES7: =IFERROR(IF(ISNUMBER(ER7),(ER7-AVERAGEIF('Pemetaan Variant'!$A$5:$A$32,$B7,'Pemetaan Variant'!$N$5:$N$32))/AVERAGEIF('Pemetaan Variant'!$A$5:$A$32,$B7,'Pemetaan Variant'!$N$5:$N$32)*100,"n/a"),"n/a") -> n/a | ET7: =IFERROR(IF(ISNUMBER(ES7),$C7*ES7,"n/a"),"n/a") -> n/a | EU7: =IFERROR(AVERAGEIF('Pemetaan Variant'!$A$5:$A$32,$B7,'Pemetaan Variant'!$BM$5:$BM$32),"n/a") -> n/a | EV7: =IFERROR(IF(ISNUMBER(EU7),(EU7-AVERAGEIF('Pemetaan Variant'!$A$5:$A$32,$B7,'Pemetaan Variant'!$N$5:$N$32))/AVERAGEIF('Pemetaan Variant'!$A$5:$A$32,$B7,'Pemetaan Variant'!$N$5:$N$32)*100,"n/a"),"n/a") -> n/a | EW7: =IFERROR(IF(ISNUMBER(EV7),$C7*EV7,"n/a"),"n/a") -> n/a | EX7: =IFERROR(AVERAGEIF('Pemetaan Variant'!$A$5:$A$32,$B7,'Pemetaan Variant'!$BN$5:$BN$32),"n/a") -> n/a | EY7: =IFERROR(IF(ISNUMBER(EX7),(EX7-AVERAGEIF('Pemetaan Variant'!$A$5:$A$32,$B7,'Pemetaan Variant'!$O$5:$O$32))/AVERAGEIF('Pemetaan Variant'!$A$5:$A$32,$B7,'Pemetaan Variant'!$O$5:$O$32)*100,"n/a"),"n/a") -> n/a | EZ7: =IFERROR(IF(ISNUMBER(EY7),$C7*EY7,"n/a"),"n/a") -> n/a | FA7: =IFERROR(AVERAGEIF('Pemetaan Variant'!$A$5:$A$32,$B7,'Pemetaan Variant'!$BO$5:$BO$32),"n/a") -> n/a | FB7: =IFERROR(IF(ISNUMBER(FA7),(FA7-AVERAGEIF('Pemetaan Variant'!$A$5:$A$32,$B7,'Pemetaan Variant'!$O$5:$O$32))/AVERAGEIF('Pemetaan Variant'!$A$5:$A$32,$B7,'Pemetaan Variant'!$O$5:$O$32)*100,"n/a"),"n/a") -> n/a | FC7: =IFERROR(IF(ISNUMBER(FB7),$C7*FB7,"n/a"),"n/a") -> n/a | FD7: =IFERROR(AVERAGEIF('Pemetaan Variant'!$A$5:$A$32,$B7,'Pemetaan Variant'!$BP$5:$BP$32),"n/a") -> n/a | FE7: =IFERROR(IF(ISNUMBER(FD7),(FD7-AVERAGEIF('Pemetaan Variant'!$A$5:$A$32,$B7,'Pemetaan Variant'!$O$5:$O$32))/AVERAGEIF('Pemetaan Variant'!$A$5:$A$32,$B7,'Pemetaan Variant'!$O$5:$O$32)*100,"n/a"),"n/a") -> n/a | FF7: =IFERROR(IF(ISNUMBER(FE7),$C7*FE7,"n/a"),"n/a") -> n/a | FG7: =IFERROR(AVERAGEIF('Pemetaan Variant'!$A$5:$A$32,$B7,'Pemetaan Variant'!$BQ$5:$BQ$32),"n/a") -> n/a | FH7: =IFERROR(IF(ISNUMBER(FG7),(FG7-AVERAGEIF('Pemetaan Variant'!$A$5:$A$32,$B7,'Pemetaan Variant'!$O$5:$O$32))/AVERAGEIF('Pemetaan Variant'!$A$5:$A$32,$B7,'Pemetaan Variant'!$O$5:$O$32)*100,"n/a"),"n/a") -> n/a | FI7: =IFERROR(IF(ISNUMBER(FH7),$C7*FH7,"n/a"),"n/a") -> n/a | FJ7: =IFERROR(AVERAGEIF('Pemetaan Variant'!$A$5:$A$32,$B7,'Pemetaan Variant'!$BR$5:$BR$32),"n/a") -> n/a | FK7: =IFERROR(IF(ISNUMBER(FJ7),(FJ7-AVERAGEIF('Pemetaan Variant'!$A$5:$A$32,$B7,'Pemetaan Variant'!$O$5:$O$32))/AVERAGEIF('Pemetaan Variant'!$A$5:$A$32,$B7,'Pemetaan Variant'!$O$5:$O$32)*100,"n/a"),"n/a") -> n/a | FL7: =IFERROR(IF(ISNUMBER(FK7),$C7*FK7,"n/a"),"n/a") -> n/a | FO7: =IFERROR(ABS(F7),0) -> 0 | FP7: =IFERROR(ABS(I7),0) -> 0.0083543584 | FQ7: =IFERROR(ABS(L7),0) -> 0.041771792 | FR7: =IFERROR(ABS(O7),0) -> 0.041771792 | FS7: =IFERROR(ABS(R7),0) -> 0.041771792 | FT7: =IFERROR(ABS(U7),0) -> 0.013683863 | FU7: =IFERROR(ABS(X7),0) -> 0.013683863 | FV7: =IFERROR(ABS(AA7),0) -> 0.013683863 | FW7: =IFERROR(ABS(AD7),0) -> 0.013683863 | FX7: =IFERROR(ABS(AG7),0) -> 0 | FY7: =IFERROR(ABS(AJ7),0) -> 0 | FZ7: =IFERROR(ABS(AM7),0) -> 0 | GA7: =IFERROR(ABS(AP7),0) -> 0 | GB7: =IFERROR(ABS(AS7),0) -> 0 | GC7: =IFERROR(ABS(AV7),0) -> 0 | GD7: =IFERROR(ABS(AY7),0) -> 0 | GE7: =IFERROR(ABS(BB7),0) -> 0 | GF7: =IFERROR(ABS(BE7),0) -> 0 | GG7: =IFERROR(ABS(BH7),0) -> 0 | GH7: =IFERROR(ABS(BK7),0) -> 0 | GI7: =IFERROR(ABS(BN7),0) -> 0 | GJ7: =IFERROR(ABS(BQ7),0) -> 0 | GK7: =IFERROR(ABS(BT7),0) -> 0 | GL7: =IFERROR(ABS(BW7),0) -> 0 | GM7: =IFERROR(ABS(BZ7),0) -> 0 | GN7: =IFERROR(ABS(CC7),0) -> 0 | GO7: =IFERROR(ABS(CF7),0) -> 0 | GP7: =IFERROR(ABS(CI7),0) -> 0.20943912 | GQ7: =IFERROR(ABS(CL7),0) -> 0.16117485 | GR7: =IFERROR(ABS(CO7),0) -> 0.16117485 | GS7: =IFERROR(ABS(CR7),0) -> 0.16117485 | GT7: =IFERROR(ABS(CU7),0) -> 0.16117485 | GU7: =IFERROR(ABS(CX7),0) -> 0.16117485 | GV7: =IFERROR(ABS(DA7),0) -> 0.79366405 | GW7: =IFERROR(ABS(DD7),0) -> 0.79366405 | GX7: =IFERROR(ABS(DG7),0) -> 0.79366405 | GY7: =IFERROR(ABS(DJ7),0) -> 0.79366405 | GZ7: =IFERROR(ABS(DM7),0) -> 0 | HA7: =IFERROR(ABS(DP7),0) -> 0 | HB7: =IFERROR(ABS(DS7),0) -> 0 | HC7: =IFERROR(ABS(DV7),0) -> 0 | HD7: =IFERROR(ABS(DY7),0) -> 0 | HE7: =IFERROR(ABS(EB7),0) -> 0 | HF7: =IFERROR(ABS(EE7),0) -> 0 | HG7: =IFERROR(ABS(EH7),0) -> 0 | HH7: =IFERROR(ABS(EK7),0) -> 0 | HI7: =IFERROR(ABS(EN7),0) -> 0 | HJ7: =IFERROR(ABS(EQ7),0) -> 0 | HK7: =IFERROR(ABS(ET7),0) -> 0 | HL7: =IFERROR(ABS(EW7),0) -> 0 | HM7: =IFERROR(ABS(EZ7),0) -> 0 | HN7: =IFERROR(ABS(FC7),0) -> 0 | HO7: =IFERROR(ABS(FF7),0) -> 0 | HP7: =IFERROR(ABS(FI7),0) -> 0 | HQ7: =IFERROR(ABS(FL7),0) -> 0
